<?xml version="1.0" encoding="utf-8"?>
<!-- Mentee Robotics LTD -->
<robot name="robot">
  <link name="base_link">
    <inertial>
      <origin xyz="-0.052449 -0.013979 0.000160229" rpy="0.0 0.0 0.0" />
      <mass value="0.0800363" />
      <inertia ixx="1.12535e-05" ixy="-6.02926e-06" ixz="-5.49146e-07" iyy="3.27864e-05" iyz="-3.63626e-08" izz="4.08345e-05" />
    </inertial>
    <visual>
      <origin xyz="0.0 0.0 0.0" rpy="0.0 0.0 0.0" />
      <geometry>
        <mesh filename="../meshes/base_link/component_9_21-344-24.STL" />
      </geometry>
      <material name="Aluminum_Cast">
        <color rgba="0.555 0.555 0.555 1.0" />
      </material>
    </visual>
    <visual>
      <origin xyz="0.0 0.0 0.0" rpy="0.0 0.0 0.0" />
      <geometry>
        <mesh filename="../meshes/base_link/component_10_21-174.STL" />
      </geometry>
      <material name="Aluminum_Cast">
        <color rgba="0.555 0.555 0.555 1.0" />
      </material>
    </visual>
    <visual>
      <origin xyz="0.0 0.0 0.0" rpy="0.0 0.0 0.0" />
      <geometry>
        <mesh filename="../meshes/base_link/component_13_21-750.STL" />
      </geometry>
      <material name="Aluminum_Cast">
        <color rgba="0.555 0.555 0.555 1.0" />
      </material>
    </visual>
    <visual>
      <origin xyz="0.0 0.0 0.0" rpy="0.0 0.0 0.0" />
      <geometry>
        <mesh filename="../meshes/base_link/component_14_21-1235.STL" />
      </geometry>
      <material name="Aluminum_Cast">
        <color rgba="0.555 0.555 0.555 1.0" />
      </material>
    </visual>
    <visual>
      <origin xyz="0.0 0.0 0.0" rpy="0.0 0.0 0.0" />
      <geometry>
        <mesh filename="../meshes/base_link/component_18_21-132.STL" />
      </geometry>
      <material name="Aluminum_Cast">
        <color rgba="0.555 0.555 0.555 1.0" />
      </material>
    </visual>
    <visual>
      <origin xyz="0.0 0.0 0.0" rpy="0.0 0.0 0.0" />
      <geometry>
        <mesh filename="../meshes/base_link/component_20_21-382.STL" />
      </geometry>
      <material name="Aluminum_Cast">
        <color rgba="0.555 0.555 0.555 1.0" />
      </material>
    </visual>
  </link>
  <joint name="b1" type="prismatic">
    <origin xyz="-0.043443 -0.009 0.0" rpy="1.5708 0.0 1.5708" />
    <parent link="base_link" />
    <child link="b1_link" />
    <axis xyz="0.0 0.0 1.0" />
    <limit lower="0.0" upper="0.038" effort="200.0" velocity="0.013" />
  </joint>
  <link name="b1_link">
    <inertial>
      <origin xyz="0.000428975 2.44163e-12 0.00138155" rpy="0.0 0.0 0.0" />
      <mass value="0.0174368" />
      <inertia ixx="9.95596e-07" ixy="3.56986e-16" ixz="9.58784e-09" iyy="8.81696e-07" iyz="1.22497e-16" izz="8.20705e-07" />
    </inertial>
    <visual>
      <origin xyz="0.0 0.0 0.0" rpy="0.0 0.0 0.0" />
      <geometry>
        <mesh filename="../meshes/b1_link/component_2_21-1268.STL" />
      </geometry>
      <material name="Aluminum_Cast">
        <color rgba="0.555 0.555 0.555 1.0" />
      </material>
    </visual>
    <visual>
      <origin xyz="0.0 0.0 0.0" rpy="0.0 0.0 0.0" />
      <geometry>
        <mesh filename="../meshes/b1_link/component_3_21-1269.STL" />
      </geometry>
      <material name="Aluminum_Cast">
        <color rgba="0.555 0.555 0.555 1.0" />
      </material>
    </visual>
  </link>
  <joint name="b2" type="revolute">
    <origin xyz="0.0 0.0 0.0121" rpy="1.5708 0.0 3.1416" />
    <parent link="b1_link" />
    <child link="b2_link" />
    <axis xyz="0.0 0.0 1.0" />
    <limit lower="-3.14" upper="3.14" effort="0.0" velocity="0.0" />
  </joint>
  <link name="b2_link">
    <inertial>
      <origin xyz="0.00211067 0.00927558 -0.000101495" rpy="0.0 0.0 0.0" />
      <mass value="0.00547861" />
      <inertia ixx="5.25734e-07" ixy="1.31598e-08" ixz="1.77435e-09" iyy="3.14583e-07" iyz="3.50929e-10" izz="3.3173e-07" />
    </inertial>
    <visual>
      <origin xyz="0.0 0.0 0.0" rpy="0.0 0.0 0.0" />
      <geometry>
        <mesh filename="../meshes/b2_link/component_0_21-1284.STL" />
      </geometry>
      <material name="Aluminum_Cast">
        <color rgba="0.555 0.555 0.555 1.0" />
      </material>
    </visual>
    <visual>
      <origin xyz="0.0 0.0 0.0" rpy="0.0 0.0 0.0" />
      <geometry>
        <mesh filename="../meshes/b2_link/component_1_21-1285.STL" />
      </geometry>
      <material name="Aluminum_Cast">
        <color rgba="0.555 0.555 0.555 1.0" />
      </material>
    </visual>
    <visual>
      <origin xyz="0.0 0.0 0.0" rpy="0.0 0.0 0.0" />
      <geometry>
        <mesh filename="../meshes/b2_link/component_2_21-215.STL" />
      </geometry>
      <material name="Aluminum_Cast">
        <color rgba="0.555 0.555 0.555 1.0" />
      </material>
    </visual>
    <visual>
      <origin xyz="0.0 0.0 0.0" rpy="0.0 0.0 0.0" />
      <geometry>
        <mesh filename="../meshes/b2_link/component_3_21-219.STL" />
      </geometry>
      <material name="Aluminum_Cast">
        <color rgba="0.555 0.555 0.555 1.0" />
      </material>
    </visual>
    <visual>
      <origin xyz="0.0 0.0 0.0" rpy="0.0 0.0 0.0" />
      <geometry>
        <mesh filename="../meshes/b2_link/component_4_21-229.STL" />
      </geometry>
      <material name="Aluminum_Cast">
        <color rgba="0.555 0.555 0.555 1.0" />
      </material>
    </visual>
    <visual>
      <origin xyz="0.0 0.0 0.0" rpy="0.0 0.0 0.0" />
      <geometry>
        <mesh filename="../meshes/b2_link/component_5_21-253.STL" />
      </geometry>
      <material name="Aluminum_Cast">
        <color rgba="0.555 0.555 0.555 1.0" />
      </material>
    </visual>
  </link>
  <joint name="b3" type="revolute">
    <origin xyz="-0.0013297 0.018452 0.0" rpy="0.0 0.0 1.6427" />
    <parent link="b2_link" />
    <child link="b3_link" />
    <axis xyz="0.0 0.0 1.0" />
    <limit lower="-3.14" upper="3.14" effort="0.0" velocity="0.0" />
  </joint>
  <link name="b3_link">
    <inertial>
      <origin xyz="0.00958045 -0.00252802 1.56092e-11" rpy="0.0 0.0 0.0" />
      <mass value="0.00488675" />
      <inertia ixx="2.10296e-07" ixy="1.55018e-08" ixz="3.56279e-16" iyy="2.22375e-07" iyz="5.85915e-16" izz="2.32584e-07" />
    </inertial>
    <visual>
      <origin xyz="0.0 0.0 0.0" rpy="0.0 0.0 0.0" />
      <geometry>
        <mesh filename="../meshes/b3_link/component_0_21-481.STL" />
      </geometry>
      <material name="Aluminum_Cast">
        <color rgba="0.555 0.555 0.555 1.0" />
      </material>
    </visual>
    <visual>
      <origin xyz="0.0 0.0 0.0" rpy="0.0 0.0 0.0" />
      <geometry>
        <mesh filename="../meshes/b3_link/component_1_21-708.STL" />
      </geometry>
      <material name="Aluminum_Cast">
        <color rgba="0.555 0.555 0.555 1.0" />
      </material>
    </visual>
    <visual>
      <origin xyz="0.0 0.0 0.0" rpy="0.0 0.0 0.0" />
      <geometry>
        <mesh filename="../meshes/b3_link/component_2_21-25.STL" />
      </geometry>
      <material name="Aluminum_Cast">
        <color rgba="0.555 0.555 0.555 1.0" />
      </material>
    </visual>
  </link>
  <joint name="b3f1" type="revolute">
    <origin xyz="0.013409 0.0067239 0.0" rpy="0.0 0.0 -0.07194" />
    <parent link="b3_link" />
    <child link="b3f1_link" />
    <axis xyz="0.0 0.0 1.0" />
    <limit lower="-3.14" upper="3.14" effort="0.0" velocity="0.0" />
  </joint>
  <link name="b3f1_link" />
  <joint name="b4" type="revolute">
    <origin xyz="0.012527 -0.0082502 0.0" rpy="0.0 0.0 -0.61572" />
    <parent link="b3_link" />
    <child link="b4_link" />
    <axis xyz="0.0 0.0 1.0" />
    <limit lower="-3.14" upper="3.14" effort="0.0" velocity="0.0" />
  </joint>
  <link name="b4_link">
    <inertial>
      <origin xyz="0.0158273 0.0115368 -4.23228e-08" rpy="0.0 0.0 0.0" />
      <mass value="0.0122238" />
      <inertia ixx="9.60638e-07" ixy="-7.04268e-07" ixz="3.93305e-12" iyy="1.38373e-06" iyz="-4.55396e-12" izz="1.67673e-06" />
    </inertial>
    <visual>
      <origin xyz="0.0 0.0 0.0" rpy="0.0 0.0 0.0" />
      <geometry>
        <mesh filename="../meshes/b4_link/component_0_21-625.STL" />
      </geometry>
      <material name="Aluminum_Cast">
        <color rgba="0.555 0.555 0.555 1.0" />
      </material>
    </visual>
    <visual>
      <origin xyz="0.0 0.0 0.0" rpy="0.0 0.0 0.0" />
      <geometry>
        <mesh filename="../meshes/b4_link/component_1_21-490.STL" />
      </geometry>
      <material name="Aluminum_Cast">
        <color rgba="0.555 0.555 0.555 1.0" />
      </material>
    </visual>
  </link>
  <joint name="b4f2" type="revolute">
    <origin xyz="0.030995 0.028026 0.0" rpy="0.0 0.0 0.5755" />
    <parent link="b4_link" />
    <child link="b4f2_link" />
    <axis xyz="0.0 0.0 1.0" />
    <limit lower="-3.14" upper="3.14" effort="0.0" velocity="0.0" />
  </joint>
  <link name="b4f2_link" />
  <joint name="f1" type="revolute">
    <origin xyz="0.0 0.0 0.0" rpy="0.0 0.0 0.0" />
    <parent link="base_link" />
    <child link="f1_link" />
    <axis xyz="0.0 0.0 1.0" />
    <limit lower="0.0" upper="1.57" effort="0.0" velocity="0.0" />
  </joint>
  <link name="f1_link">
    <inertial>
      <origin xyz="0.0271401 0.000679815 3.9196e-09" rpy="0.0 0.0 0.0" />
      <mass value="0.0163621" />
      <inertia ixx="4.99077e-07" ixy="2.32367e-07" ixz="-3.52986e-14" iyy="2.91678e-06" iyz="-1.56807e-13" izz="2.89853e-06" />
    </inertial>
    <visual>
      <origin xyz="0.0 0.0 0.0" rpy="0.0 0.0 0.0" />
      <geometry>
        <mesh filename="../meshes/f1_link/component_1_21-1257-21.STL" />
      </geometry>
      <material name="Aluminum_Cast">
        <color rgba="0.555 0.555 0.555 1.0" />
      </material>
    </visual>
    <visual>
      <origin xyz="0.0 0.0 0.0" rpy="0.0 0.0 0.0" />
      <geometry>
        <mesh filename="../meshes/f1_link/component_2_21-589.STL" />
      </geometry>
      <material name="Aluminum_Cast">
        <color rgba="0.555 0.555 0.555 1.0" />
      </material>
    </visual>
    <visual>
      <origin xyz="0.0 0.0 0.0" rpy="0.0 0.0 0.0" />
      <geometry>
        <mesh filename="../meshes/f1_link/component_0_21-1257-22.STL" />
      </geometry>
      <material name="Rubber_Textured">
        <color rgba="0.111 0.111 0.111 1.0" />
      </material>
    </visual>
    <collision>
      <origin xyz="0.022 -0.005 0.0" rpy="0.0 1.5708 0.0" />
      <geometry>
        <cylinder radius="0.011" length="0.014" />
      </geometry>
    </collision>
  </link>
  <joint name="b5" type="revolute">
    <origin xyz="0.049 -0.0069282 0.0" rpy="0.0 0.0 0.031714" />
    <parent link="f1_link" />
    <child link="b5_link" />
    <axis xyz="0.0 0.0 1.0" />
    <limit lower="-3.14" upper="3.14" effort="0.0" velocity="0.0" />
  </joint>
  <link name="b5_link">
    <inertial>
      <origin xyz="0.0161194 0.00199652 7.51207e-10" rpy="0.0 0.0 0.0" />
      <mass value="0.00295766" />
      <inertia ixx="4.13467e-08" ixy="-8.32874e-08" ixz="-4.55606e-15" iyy="4.4953e-07" iyz="-8.27097e-15" izz="4.77488e-07" />
    </inertial>
    <visual>
      <origin xyz="0.0 0.0 0.0" rpy="0.0 0.0 0.0" />
      <geometry>
        <mesh filename="../meshes/b5_link/component_2_21-585.STL" />
      </geometry>
      <material name="Aluminum_Cast">
        <color rgba="0.555 0.555 0.555 1.0" />
      </material>
    </visual>
  </link>
  <joint name="b5f3" type="revolute">
    <origin xyz="0.030936 0.0072089 0.0" rpy="0.0 0.0 -1.6025" />
    <parent link="b5_link" />
    <child link="b5f3_link" />
    <axis xyz="0.0 0.0 1.0" />
    <limit lower="-3.14" upper="3.14" effort="0.0" velocity="0.0" />
  </joint>
  <link name="b5f3_link" />
  <joint name="f2" type="revolute">
    <origin xyz="0.045 0.0 0.0" rpy="0.0 0.0 0.0" />
    <parent link="f1_link" />
    <child link="f2_link" />
    <axis xyz="0.0 0.0 1.0" />
    <limit lower="0.0" upper="1.66" effort="0.0" velocity="0.0" />
  </joint>
  <link name="f2_link">
    <inertial>
      <origin xyz="0.0124792 -0.00662953 2.63976e-06" rpy="0.0 0.0 0.0" />
      <mass value="0.0150424" />
      <inertia ixx="8.93249e-07" ixy="1.5032e-07" ixz="5.85245e-09" iyy="2.11235e-06" iyz="-1.00866e-08" izz="2.01909e-06" />
    </inertial>
    <visual>
      <origin xyz="0.0 0.0 0.0" rpy="0.0 0.0 0.0" />
      <geometry>
        <mesh filename="../meshes/f2_link/component_2_21-1201.STL" />
      </geometry>
      <material name="Aluminum_Cast">
        <color rgba="0.555 0.555 0.555 1.0" />
      </material>
    </visual>
    <visual>
      <origin xyz="0.0 0.0 0.0" rpy="0.0 0.0 0.0" />
      <geometry>
        <mesh filename="../meshes/f2_link/component_3_21-1202.STL" />
      </geometry>
      <material name="Aluminum_Cast">
        <color rgba="0.555 0.555 0.555 1.0" />
      </material>
    </visual>
    <visual>
      <origin xyz="0.0 0.0 0.0" rpy="0.0 0.0 0.0" />
      <geometry>
        <mesh filename="../meshes/f2_link/component_6_21-611.STL" />
      </geometry>
      <material name="Aluminum_Cast">
        <color rgba="0.555 0.555 0.555 1.0" />
      </material>
    </visual>
    <visual>
      <origin xyz="0.0 0.0 0.0" rpy="0.0 0.0 0.0" />
      <geometry>
        <mesh filename="../meshes/f2_link/component_7_21-619.STL" />
      </geometry>
      <material name="Aluminum_Cast">
        <color rgba="0.555 0.555 0.555 1.0" />
      </material>
    </visual>
    <visual>
      <origin xyz="0.0 0.0 0.0" rpy="0.0 0.0 0.0" />
      <geometry>
        <mesh filename="../meshes/f2_link/component_1_21-1211-23.STL" />
      </geometry>
      <material name="Rubber_Textured">
        <color rgba="0.111 0.111 0.111 1.0" />
      </material>
    </visual>
    <collision>
      <origin xyz="0.0107167 -0.00666353 0.0001" rpy="0.0 0.0 0.0" />
      <geometry>
        <sphere radius="0.011" />
      </geometry>
    </collision>
  </link>
  <joint name="f3" type="revolute">
    <origin xyz="0.031204 -0.0059417 0.0" rpy="0.0 0.0 0.031714" />
    <parent link="f2_link" />
    <child link="f3_link" />
    <axis xyz="0.0 0.0 1.0" />
    <limit lower="0.0" upper="1.4486" effort="0.0" velocity="0.0" />
  </joint>
  <link name="f3_link">
    <inertial>
      <origin xyz="0.0109887 0.0032088 -5.39167e-09" rpy="0.0 0.0 0.0" />
      <mass value="0.0157411" />
      <inertia ixx="7.15188e-07" ixy="7.76911e-08" ixz="-3.66384e-13" iyy="1.04173e-06" iyz="-6.4345e-13" izz="1.07766e-06" />
    </inertial>
    <visual>
      <origin xyz="0.0 0.0 0.0" rpy="0.0 0.0 0.0" />
      <geometry>
        <mesh filename="../meshes/f3_link/component_0_21-41.STL" />
      </geometry>
      <material name="Aluminum_Cast">
        <color rgba="0.555 0.555 0.555 1.0" />
      </material>
    </visual>
    <visual>
      <origin xyz="0.0 0.0 0.0" rpy="0.0 0.0 0.0" />
      <geometry>
        <mesh filename="../meshes/f3_link/component_3_21-1197-22.STL" />
      </geometry>
      <material name="Aluminum_Cast">
        <color rgba="0.555 0.555 0.555 1.0" />
      </material>
    </visual>
    <visual>
      <origin xyz="0.0 0.0 0.0" rpy="0.0 0.0 0.0" />
      <geometry>
        <mesh filename="../meshes/f3_link/component_4_21-1197-24.STL" />
      </geometry>
      <material name="Rubber_Textured">
        <color rgba="0.111 0.111 0.111 1.0" />
      </material>
    </visual>
    <collision>
      <origin xyz="0.0148682 0.00353726 0.0" rpy="0.0 0.0 0.0" />
      <geometry>
        <sphere radius="0.009" />
      </geometry>
    </collision>
  </link>
</robot>