<?xml version="1.0" encoding="utf-8"?>
<!-- Mentee Robotics LTD -->
<robot name="robot">
  <link name="base_link">
    <inertial>
      <origin xyz="-0.022035 0.0015817 -0.0085437" rpy="0.0 0.0 0.0" />
      <mass value="0.022212" />
      <inertia ixx="2.0412e-06" ixy="8.5606e-08" ixz="-1.4389e-06" iyy="1.0286e-05" iyz="4.141e-09" izz="1.0785e-05" />
    </inertial>
    <visual>
      <origin xyz="0.0 0.0 0.0" rpy="0.0 0.0 0.0" />
      <geometry>
        <mesh filename="../meshes/base_link/component_0_77.STL" />
      </geometry>
      <material name="Aluminum_Cast">
        <color rgba="0.555 0.555 0.555 1.0" />
      </material>
    </visual>
  </link>
  <joint name="f1" type="revolute">
    <origin xyz="0.025 0.0 -0.0065" rpy="-1.5708 0.0 3.1416" />
    <parent link="base_link" />
    <child link="f1_link" />
    <axis xyz="0.0 0.0 1.0" />
    <limit lower="0.0" upper="1.2217" effort="3.0" velocity="0.866" />
  </joint>
  <link name="f1_link">
    <inertial>
      <origin xyz="-0.024702 -0.0016844 5.9351e-09" rpy="0.0 0.0 0.0" />
      <mass value="0.013981" />
      <inertia ixx="3.5007e-07" ixy="8.8989e-09" ixz="-2.7279e-14" iyy="2.0695e-06" iyz="-1.8122e-14" izz="1.9544e-06" />
    </inertial>
    <visual>
      <origin xyz="0.0 0.0 0.0" rpy="0.0 0.0 0.0" />
      <geometry>
        <mesh filename="../meshes/f1_link/component_0_23.STL" />
      </geometry>
      <material name="Aluminum_Cast">
        <color rgba="0.555 0.555 0.555 1.0" />
      </material>
    </visual>
    <visual>
      <origin xyz="0.0 0.0 0.0" rpy="0.0 0.0 0.0" />
      <geometry>
        <mesh filename="../meshes/f1_link/component_2_24-21.STL" />
      </geometry>
      <material name="Aluminum_Cast">
        <color rgba="0.555 0.555 0.555 1.0" />
      </material>
    </visual>
    <visual>
      <origin xyz="0.0 0.0 0.0" rpy="0.0 0.0 0.0" />
      <geometry>
        <mesh filename="../meshes/f1_link/component_1_24-22.STL" />
      </geometry>
      <material name="Rubber_Textured">
        <color rgba="0.111 0.111 0.111 1.0" />
      </material>
    </visual>
    <collision>
      <origin xyz="-0.022 0.005 0.0" rpy="0.0 1.5708 0.0" />
      <geometry>
        <cylinder radius="0.011" length="0.014" />
      </geometry>
    </collision>
  </link>
  <joint name="f2" type="revolute">
    <origin xyz="-0.045 0.0 0.0" rpy="0.0 0.0 3.1416" />
    <parent link="f1_link" />
    <child link="f2_link" />
    <axis xyz="0.0 0.0 1.0" />
    <limit lower="0.0" upper="1.0472" effort="0.0" velocity="0.0" />
  </joint>
  <link name="f2_link">
    <inertial>
      <origin xyz="0.019715 -0.0046347 -0.00011604" rpy="0.0 0.0 0.0" />
      <mass value="0.018642" />
      <inertia ixx="9.1068e-07" ixy="-1.3561e-07" ixz="-5.5927e-09" iyy="4.4551e-06" iyz="-7.101e-09" izz="4.3649e-06" />
    </inertial>
    <visual>
      <origin xyz="0.0 0.0 0.0" rpy="0.0 0.0 0.0" />
      <geometry>
        <mesh filename="../meshes/f2_link/component_1_25.STL" />
      </geometry>
      <material name="Aluminum_Cast">
        <color rgba="0.555 0.555 0.555 1.0" />
      </material>
    </visual>
    <visual>
      <origin xyz="0.0 0.0 0.0" rpy="0.0 0.0 0.0" />
      <geometry>
        <mesh filename="../meshes/f2_link/component_2_26.STL" />
      </geometry>
      <material name="Aluminum_Cast">
        <color rgba="0.555 0.555 0.555 1.0" />
      </material>
    </visual>
    <visual>
      <origin xyz="0.0 0.0 0.0" rpy="0.0 0.0 0.0" />
      <geometry>
        <mesh filename="../meshes/f2_link/component_0_27-22.STL" />
      </geometry>
      <material name="Rubber_Textured">
        <color rgba="0.111 0.111 0.111 1.0" />
      </material>
    </visual>
    <collision>
      <origin xyz="0.0124972 -0.0024282 0.0" rpy="0.0 0.0 0.0" />
      <geometry>
        <sphere radius="0.009" />
      </geometry>
    </collision>
    <collision>
      <origin xyz="0.0365951 -0.00188703 0.0" rpy="0.0 0.0 0.0" />
      <geometry>
        <sphere radius="0.009" />
      </geometry>
    </collision>
  </link>
</robot>