<?xml version="1.0" encoding="utf-8"?>
<!-- Mentee Robotics LTD -->
<robot name="robot">
  <link name="base_link">
    <inertial>
      <origin xyz="0.22832 -0.01203 0.030782" rpy="0.0 0.0 0.0" />
      <mass value="11.65" />
      <inertia ixx="0.050664" ixy="-0.00310967" ixz="5.80938e-05" iyy="0.114058" iyz="-0.00189436" izz="0.127873" />
    </inertial>
    <visual>
      <origin xyz="0.0 0.0 0.0" rpy="0.0 0.0 0.0" />
      <geometry>
        <mesh filename="../meshes/base_link.STL" />
      </geometry>
      <material name="base_material">
        <color rgba="0.78 0.76 0.74 1.0" />
      </material>
    </visual>
    <collision>
      <origin xyz="0.215 0.0 0.03" rpy="3.14159 -1.57056 0.0" />
      <geometry>
        <cylinder radius="0.08" length="0.2" />
      </geometry>
    </collision>
  </link>
  <joint name="knee" type="revolute">
    <origin xyz="0.43 0.0 0.0" rpy="0.0 0.0 0.0" />
    <parent link="base_link" />
    <child link="knee_link" />
    <axis xyz="0.0 0.0 1.0" />
    <limit lower="0.0" upper="1.8" effort="0.0" velocity="0.0" />
  </joint>
  <link name="knee_link">
    <inertial>
      <origin xyz="0.23203 0.021459 -0.00024168" rpy="0.0 0.0 0.0" />
      <mass value="7.366" />
      <inertia ixx="0.0213507" ixy="-0.00919404" ixz="-0.000213904" iyy="0.0833769" iyz="-8.46929e-05" izz="0.0864274" />
    </inertial>
    <visual>
      <origin xyz="0.0 0.0 0.0" rpy="0.0 0.0 0.0" />
      <geometry>
        <mesh filename="../meshes/knee_link.STL" />
      </geometry>
      <material name="knee_material">
        <color rgba="0.2 0.4 0.7 1.0" />
      </material>
    </visual>
    <collision>
      <origin xyz="0.215 0.0 0.0" rpy="3.14159 -1.5708 0.0" />
      <geometry>
        <cylinder radius="0.08" length="0.2" />
      </geometry>
    </collision>
  </link>
  <joint name="ankle_pitch" type="revolute">
    <origin xyz="0.43 0.0 0.0" rpy="0.0 0.0 0.0" />
    <parent link="knee_link" />
    <child link="ankle_pitch_link" />
    <axis xyz="0.0 0.0 1.0" />
    <limit lower="-0.7" upper="0.31" effort="0.0" velocity="0.0" />
  </joint>
  <link name="ankle_pitch_link">
    <inertial>
      <origin xyz="-0.0016933 -0.0003716 1.5098e-06" rpy="0.0 0.0 0.0" />
      <mass value="0.306" />
      <inertia ixx="9.54935e-05" ixy="-5.14681e-06" ixz="4.94153e-09" iyy="7.7257e-05" iyz="-4.89492e-09" izz="7.81859e-05" />
    </inertial>
    <visual>
      <origin xyz="0.0 0.0 0.0" rpy="0.0 0.0 0.0" />
      <geometry>
        <mesh filename="../meshes/ankle_pitch_link.STL" />
      </geometry>
      <material name="ankle_pitch_material">
        <color rgba="0.65 0.62 0.59 1.0" />
      </material>
    </visual>
  </link>
  <joint name="ankle_roll" type="revolute">
    <origin xyz="0.0 0.0 0.0" rpy="-1.5708 0.0 3.1416" />
    <parent link="ankle_pitch_link" />
    <child link="ankle_roll_link_ee" />
    <axis xyz="0.0 0.0 1.0" />
    <limit lower="-0.6" upper="0.6" effort="0.0" velocity="0.0" />
  </joint>
  <link name="ankle_roll_link_ee" />
</robot>