<?xml version="1.0" encoding="utf-8"?>
<!-- Mentee Robotics LTD -->
<robot name="robot">
  <link name="left_upper_arm">
    <inertial>
      <origin xyz="0.00298623 0.034298 0.000784517" rpy="0.0 0.0 0.0" />
      <mass value="1.3" />
      <inertia ixx="0.00158171" ixy="-0.0001305" ixz="-4.02266e-05" iyy="0.00216046" iyz="-3.56895e-05" izz="0.00171379" />
    </inertial>
    <visual>
      <origin xyz="0.0 0.0 0.0" rpy="0.0 0.0 0.0" />
      <geometry>
        <mesh filename="../meshes/left_upper_arm.STL" />
      </geometry>
      <material name="left_upper_arm_material">
        <color rgba="0.18 0.18 0.18 1.0" />
      </material>
    </visual>
  </link>
  <joint name="left_shoulder_pitch" type="revolute">
    <origin xyz="5e-05 0.1519 0.0" rpy="-1.5708 0.0 0.0" />
    <parent link="left_upper_arm" />
    <child link="left_shoulder_pitch_link" />
    <axis xyz="0.0 0.0 1.0" />
    <limit lower="-3.9" upper="5.0" effort="80.0" velocity="4.9" />
  </joint>
  <link name="left_shoulder_pitch_link">
    <inertial>
      <origin xyz="-0.000934648 -2.4153e-05 -0.0285522" rpy="0.0 0.0 0.0" />
      <mass value="1.847" />
      <inertia ixx="0.00466029" ixy="-6.52164e-07" ixz="-2.29793e-06" iyy="0.00432935" iyz="3.55533e-07" izz="0.0018136" />
    </inertial>
    <visual>
      <origin xyz="0.0 0.0 0.0" rpy="0.0 0.0 0.0" />
      <geometry>
        <mesh filename="../meshes/left_shoulder_pitch_link.STL" />
      </geometry>
      <material name="left_shoulder_pitch_material">
        <color rgba="0.18 0.18 0.18 1.0" />
      </material>
    </visual>
  </link>
  <joint name="left_shoulder_roll" type="revolute">
    <origin xyz="0.0 0.0 0.0" rpy="-1.5708 0.0 -1.5708" />
    <parent link="left_shoulder_pitch_link" />
    <child link="left_shoulder_roll_link" />
    <axis xyz="0.0 0.0 1.0" />
    <limit lower="-1.51" upper="0.45" effort="80.0" velocity="4.9" />
  </joint>
  <link name="left_shoulder_roll_link">
    <inertial>
      <origin xyz="-0.00182043 -0.0834498 0.00139231" rpy="0.0 0.0 0.0" />
      <mass value="1.278" />
      <inertia ixx="0.00324043" ixy="-0.000134663" ixz="-3.80074e-06" iyy="0.00172796" iyz="-0.000133397" izz="0.00287815" />
    </inertial>
    <visual>
      <origin xyz="0.0 0.0 0.0" rpy="0.0 0.0 0.0" />
      <geometry>
        <mesh filename="../meshes/left_shoulder_roll_link.STL" />
      </geometry>
      <material name="left_shoulder_roll_material">
        <color rgba="0.18 0.18 0.18 1.0" />
      </material>
    </visual>
    <collision>
      <origin xyz="0.0 -0.084 0.0" rpy="-1.5708 0.0 0.0" />
      <geometry>
        <cylinder radius="0.045" length="0.17" />
      </geometry>
    </collision>
  </link>
  <joint name="left_shoulder_cover" type="fixed">
    <origin xyz="0.0 0.0 0.0" rpy="0.0 0.0 0.0" />
    <parent link="left_shoulder_roll_link" />
    <child link="left_shoulder_cover" />
  </joint>
  <link name="left_shoulder_cover">
    <inertial>
      <origin xyz="0.0282155 -0.112511 0.0" rpy="0.0 0.0 0.0" />
      <mass value="0.154" />
      <inertia ixx="0.000859073" ixy="0.000135709" ixz="-1.07235e-08" iyy="0.000346544" iyz="-1.65802e-08" izz="0.000658834" />
    </inertial>
    <visual>
      <origin xyz="0.0 0.0 0.0" rpy="0.0 0.0 0.0" />
      <geometry>
        <mesh filename="../meshes/left_shoulder_cover.STL" />
      </geometry>
      <material name="left_shoulder_cover_material">
        <color rgba="0.78 0.78 0.78 1.0" />
      </material>
    </visual>
  </link>
  <joint name="left_shoulder_yaw" type="revolute">
    <origin xyz="0.0 0.0 0.0" rpy="-1.5708 0.0 -3.14159" />
    <parent link="left_shoulder_roll_link" />
    <child link="left_shoulder_yaw_link" />
    <axis xyz="0.0 0.0 1.0" />
    <limit lower="-1.7" upper="1.7" effort="25.0" velocity="9.8" />
  </joint>
  <link name="left_shoulder_yaw_link">
    <inertial>
      <origin xyz="-0.000312267 2.25232e-05 0.19908" rpy="0.0 0.0 0.0" />
      <mass value="1.551" />
      <inertia ixx="0.00744648" ixy="5.72923e-07" ixz="-3.83687e-05" iyy="0.00753197" iyz="-3.56196e-06" izz="0.00114053" />
    </inertial>
    <visual>
      <origin xyz="0.0 0.0 0.0" rpy="0.0 0.0 0.0" />
      <geometry>
        <mesh filename="../meshes/left_shoulder_yaw_link.STL" />
      </geometry>
      <material name="left_shoulder_yaw_material">
        <color rgba="0.18 0.18 0.18 1.0" />
      </material>
    </visual>
  </link>
  <joint name="left_elbow" type="revolute">
    <origin xyz="0.0 0.0 0.2729" rpy="-1.5708 0.0 -1.5708" />
    <parent link="left_shoulder_yaw_link" />
    <child link="left_elbow_link" />
    <axis xyz="0.0 0.0 1.0" />
    <limit lower="-1.7" upper="2.05" effort="25.0" velocity="9.8" />
  </joint>
  <link name="left_elbow_link">
    <inertial>
      <origin xyz="0.0 0.0 0.0148178" rpy="0.0 0.0 0.0" />
      <mass value="0.175" />
      <inertia ixx="3.92381e-05" ixy="0.0" ixz="0.0" iyy="3.92381e-05" iyz="0.0" izz="3.88778e-05" />
    </inertial>
    <visual>
      <origin xyz="0.0 0.0 0.0" rpy="0.0 0.0 0.0" />
      <geometry>
        <mesh filename="../meshes/left_elbow_link.STL" />
      </geometry>
      <material name="left_elbow_material">
        <color rgba="0.18 0.18 0.18 1.0" />
      </material>
    </visual>
  </link>
  <joint name="left_forearm_ee" type="fixed">
    <origin xyz="0.0 0.0 0.0" rpy="0.0 0.0 0.0" />
    <parent link="left_elbow_link" />
    <child link="left_forearm_ee_link" />
  </joint>
  <link name="left_forearm_ee_link" />
</robot>