<?xml version="1.0" encoding="utf-8"?>
<!-- Mentee Robotics LTD -->
<robot name="robot">
  <link name="left_leg_ee">
    <inertial>
      <origin xyz="-0.195767 -0.000171576 0.00397018" rpy="0.0 0.0 0.0" />
      <mass value="1.823" />
      <inertia ixx="0.00176052" ixy="3.0869e-05" ixz="0.000333943" iyy="0.0113229" iyz="-9.97313e-07" izz="0.0118152" />
    </inertial>
    <visual>
      <origin xyz="0.0 0.0 0.0" rpy="0.0 0.0 0.0" />
      <geometry>
        <mesh filename="../meshes/left_leg_ee.STL" />
      </geometry>
      <material name="left_leg_ee_material">
        <color rgba="0.5 0.5 0.5 1.0" />
      </material>
    </visual>
  </link>
  <joint name="left_knee" type="revolute">
    <origin xyz="-0.241 0.0 0.0" rpy="-3.1416 0.0 3.1416" />
    <parent link="left_leg_ee" />
    <child link="left_shin" />
    <axis xyz="0.0 0.0 1.0" />
    <limit lower="-2.1" upper="2.1" effort="80.0" velocity="5.0" />
  </joint>
  <link name="left_shin">
    <inertial>
      <origin xyz="0.247066 -7.26201e-05 0.0154983" rpy="0.0 0.0 0.0" />
      <mass value="2.352" />
      <inertia ixx="0.00252662" ixy="-1.41674e-05" ixz="-0.00215985" iyy="0.0361054" iyz="-2.98816e-07" izz="0.0361516" />
    </inertial>
    <visual>
      <origin xyz="0.0 0.0 0.0" rpy="0.0 0.0 0.0" />
      <geometry>
        <mesh filename="../meshes/left_shin.STL" />
      </geometry>
      <material name="left_shin_material">
        <color rgba="0.9 0.92 0.93 1.0" />
      </material>
    </visual>
    <collision>
      <origin xyz="0.24 0.0 0.02" rpy="0.0 1.5708 0.0" />
      <geometry>
        <cylinder radius="0.04" length="0.25" />
      </geometry>
    </collision>
  </link>
  <joint name="left_ankle_pitch" type="revolute">
    <origin xyz="0.34 0.0 0.02025" rpy="-3.1416 0.0 0.0" />
    <parent link="left_shin" />
    <child link="left_ankle_pitch" />
    <axis xyz="0.0 0.0 1.0" />
    <limit lower="-1.57" upper="0.79" effort="80.0" velocity="5.0" />
  </joint>
  <link name="left_ankle_pitch">
    <inertial>
      <origin xyz="0.000597972 0.0934241 0.00106116" rpy="0.0 0.0 0.0" />
      <mass value="1.274" />
      <inertia ixx="0.00387706" ixy="1.85475e-06" ixz="7.79692e-07" iyy="0.00163101" iyz="0.000124375" izz="0.00333208" />
    </inertial>
    <visual>
      <origin xyz="0.0 0.0 0.0" rpy="0.0 0.0 0.0" />
      <geometry>
        <mesh filename="../meshes/left_ankle_pitch.STL" />
      </geometry>
      <material name="left_ankle_pitch_material">
        <color rgba="0.2 0.2 0.2 1.0" />
      </material>
    </visual>
    <collision>
      <origin xyz="0.0 0.13 0.0" rpy="0.0 0.0 0.0" />
      <geometry>
        <sphere radius="0.04" />
      </geometry>
    </collision>
  </link>
  <joint name="left_ankle_roll" type="revolute">
    <origin xyz="0.0 0.0 0.0" rpy="-1.5708 0.0 0.0" />
    <parent link="left_ankle_pitch" />
    <child link="left_ankle_roll" />
    <axis xyz="0.0 0.0 1.0" />
    <limit lower="-0.55" upper="0.55" effort="25.0" velocity="10.0" />
  </joint>
  <link name="left_ankle_roll">
    <inertial>
      <origin xyz="-8.88178e-16 1.08143e-14 0.137718" rpy="0.0 0.0 0.0" />
      <mass value="0.175" />
      <inertia ixx="3.92381e-05" ixy="0.0" ixz="0.0" iyy="3.92381e-05" iyz="0.0" izz="3.88778e-05" />
    </inertial>
    <visual>
      <origin xyz="0.0 0.0 0.0" rpy="0.0 0.0 0.0" />
      <geometry>
        <mesh filename="../meshes/left_ankle_roll.STL" />
      </geometry>
      <material name="left_ankle_roll_material">
        <color rgba="0.87 0.87 0.89 1.0" />
      </material>
    </visual>
  </link>
  <joint name="left_foot_ee" type="fixed">
    <origin xyz="0.0 0.0 0.15485" rpy="0.0 0.0 0.0" />
    <parent link="left_ankle_roll" />
    <child link="left_foot_ee_link" />
  </joint>
  <link name="left_foot_ee_link" />
</robot>
