<?xml version="1.0" encoding="utf-8"?>
<!-- Mentee Robotics LTD -->
<robot name="robot">
  <link name="right_upper_arm">
    <inertial>
      <origin xyz="0.00298393 -0.034298 0.000780794" rpy="0.0 0.0 0.0" />
      <mass value="1.3" />
      <inertia ixx="0.00157955" ixy="0.000130574" ixz="-3.65671e-05" iyy="0.00216048" iyz="3.583e-05" izz="0.00171597" />
    </inertial>
    <visual>
      <origin xyz="0.0 0.0 0.0" rpy="0.0 0.0 0.0" />
      <geometry>
        <mesh filename="../meshes/right_upper_arm.STL" />
      </geometry>
      <material name="right_upper_arm_material">
        <color rgba="0.18 0.18 0.18 1.0" />
      </material>
    </visual>
  </link>
  <joint name="right_shoulder_pitch" type="revolute">
    <origin xyz="0.0 -0.1519 0.0" rpy="-1.5708 0.0 3.14159" />
    <parent link="right_upper_arm" />
    <child link="right_shoulder_pitch_link" />
    <axis xyz="0.0 0.0 1.0" />
    <limit lower="-1.71" upper="1.71" effort="50.0" velocity="4.2" />
  </joint>
  <link name="right_shoulder_pitch_link">
    <inertial>
      <origin xyz="0.000934648 2.4153e-05 -0.0285522" rpy="0.0 0.0 0.0" />
      <mass value="1.847" />
      <inertia ixx="0.00466029" ixy="-6.59993e-07" ixz="2.29793e-06" iyy="0.00432934" iyz="-3.55533e-07" izz="0.0018136" />
    </inertial>
    <visual>
      <origin xyz="0.0 0.0 0.0" rpy="0.0 0.0 0.0" />
      <geometry>
        <mesh filename="../meshes/right_shoulder_pitch_link.STL" />
      </geometry>
      <material name="right_shoulder_pitch_material">
        <color rgba="0.18 0.18 0.18 1.0" />
      </material>
    </visual>
  </link>
  <joint name="right_shoulder_roll" type="revolute">
    <origin xyz="0.0 0.0 0.0" rpy="-1.5708 0.0 1.5708" />
    <parent link="right_shoulder_pitch_link" />
    <child link="right_shoulder_roll_link" />
    <axis xyz="0.0 0.0 1.0" />
    <limit lower="-0.45" upper="1.51" effort="80.0" velocity="4.9" />
  </joint>
  <link name="right_shoulder_roll_link">
    <inertial>
      <origin xyz="0.00182073 -0.0834498 0.00125298" rpy="0.0 0.0 0.0" />
      <mass value="1.278" />
      <inertia ixx="0.0032409" ixy="0.000134603" ixz="2.35405e-06" iyy="0.00172843" iyz="-0.000132596" izz="0.00287815" />
    </inertial>
    <visual>
      <origin xyz="0.0 0.0 0.0" rpy="0.0 0.0 0.0" />
      <geometry>
        <mesh filename="../meshes/right_shoulder_roll_link.STL" />
      </geometry>
      <material name="right_shoulder_roll_material">
        <color rgba="0.18 0.18 0.18 1.0" />
      </material>
    </visual>
    <collision>
      <origin xyz="0.0 -0.084 0.0" rpy="-1.5708 0.0 0.0" />
      <geometry>
        <cylinder radius="0.045" length="0.17" />
      </geometry>
    </collision>
  </link>
  <joint name="right_shoulder_cover" type="fixed">
    <origin xyz="0.0 0.0 0.0" rpy="0.0 0.0 0.0" />
    <parent link="right_shoulder_roll_link" />
    <child link="right_shoulder_cover" />
  </joint>
  <link name="right_shoulder_cover">
    <inertial>
      <origin xyz="-0.0282154 -0.112511 5.05021e-05" rpy="0.0 0.0 0.0" />
      <mass value="0.154" />
      <inertia ixx="0.000859073" ixy="-0.000135709" ixz="-1.07235e-08" iyy="0.000346544" iyz="1.65802e-08" izz="0.000658834" />
    </inertial>
    <visual>
      <origin xyz="0.0 0.0 0.0" rpy="0.0 0.0 0.0" />
      <geometry>
        <mesh filename="../meshes/right_shoulder_cover.STL" />
      </geometry>
      <material name="right_shoulder_cover_material">
        <color rgba="0.78 0.78 0.78 1.0" />
      </material>
    </visual>
  </link>
  <joint name="right_shoulder_yaw" type="revolute">
    <origin xyz="0.0 0.0 0.0" rpy="-1.5708 0.0 3.14159" />
    <parent link="right_shoulder_roll_link" />
    <child link="right_shoulder_yaw_link" />
    <axis xyz="0.0 0.0 1.0" />
    <limit lower="-1.7" upper="1.7" effort="25.0" velocity="9.8" />
  </joint>
  <link name="right_shoulder_yaw_link">
    <inertial>
      <origin xyz="0.000312267 -2.25232e-05 0.19908" rpy="0.0 0.0 0.0" />
      <mass value="1.56" />
      <inertia ixx="0.00748969" ixy="5.76248e-07" ixz="3.85914e-05" iyy="0.00757568" iyz="3.58263e-06" izz="0.00114714" />
    </inertial>
    <visual>
      <origin xyz="0.0 0.0 0.0" rpy="0.0 0.0 0.0" />
      <geometry>
        <mesh filename="../meshes/right_shoulder_yaw_link.STL" />
      </geometry>
      <material name="right_shoulder_yaw_material">
        <color rgba="0.18 0.18 0.18 1.0" />
      </material>
    </visual>
  </link>
  <joint name="right_elbow" type="revolute">
    <origin xyz="0.0 0.0 0.2729" rpy="-1.5708 0.0 1.5708" />
    <parent link="right_shoulder_yaw_link" />
    <child link="right_elbow_link" />
    <axis xyz="0.0 0.0 1.0" />
    <limit lower="-2.05" upper="1.7" effort="25.0" velocity="9.8" />
  </joint>
  <link name="right_elbow_link">
    <inertial>
      <origin xyz="0.0 0.0 0.0148178" rpy="0.0 0.0 0.0" />
      <mass value="0.175" />
      <inertia ixx="3.92381e-05" ixy="0.0" ixz="0.0" iyy="3.92381e-05" iyz="0.0" izz="3.88778e-05" />
    </inertial>
    <visual>
      <origin xyz="0.0 0.0 0.0" rpy="0.0 0.0 0.0" />
      <geometry>
        <mesh filename="../meshes/right_elbow_link.STL" />
      </geometry>
      <material name="right_elbow_material">
        <color rgba="0.18 0.18 0.18 1.0" />
      </material>
    </visual>
  </link>
  <joint name="right_forearm_ee" type="fixed">
    <origin xyz="0.0 0.0 0.0" rpy="0.0 0.0 0.0" />
    <parent link="right_elbow_link" />
    <child link="right_forearm_ee_link" />
  </joint>
  <link name="right_forearm_ee_link" />
</robot>