<?xml version="1.0" encoding="utf-8"?>
<!-- Mentee Robotics LTD -->
<robot name="robot">
  <link name="base_link">
    <inertial>
      <origin xyz="-0.0221624 -0.00166695 -0.00852265" rpy="0.0 0.0 0.0" />
      <mass value="0.0223569" />
      <inertia ixx="2.06225e-06" ixy="-1.19272e-07" ixz="-1.4296e-06" iyy="1.03403e-05" iyz="2.1618e-09" izz="1.08572e-05" />
    </inertial>
    <visual>
      <origin xyz="0.0 0.0 0.0" rpy="0.0 0.0 0.0" />
      <geometry>
        <mesh filename="../meshes/base_link/component_1.STL" />
      </geometry>
      <material name="Aluminum_Anodized">
        <color rgba="0.888 0.888 0.888 1.0" />
      </material>
    </visual>
  </link>
  <joint name="f1" type="revolute">
    <origin xyz="0.025 0.0 -0.0065" rpy="-1.5708 0.0 3.14159" />
    <parent link="base_link" />
    <child link="f1_link" />
    <axis xyz="0.0 0.0 1.0" />
    <limit lower="0.0" upper="1.2217" effort="3.0" velocity="0.866" />
  </joint>
  <link name="f1_link">
    <inertial>
      <origin xyz="-0.0247024 -0.00168435 5.93506e-09" rpy="0.0 0.0 0.0" />
      <mass value="0.0139814" />
      <inertia ixx="3.50071e-07" ixy="8.89895e-09" ixz="-2.72793e-14" iyy="2.06948e-06" iyz="-1.81217e-14" izz="1.95438e-06" />
    </inertial>
    <visual>
      <origin xyz="0.0 0.0 0.0" rpy="0.0 0.0 0.0" />
      <geometry>
        <mesh filename="../meshes/f1_link/component_1.STL" />
      </geometry>
      <material name="Aluminum_Anodized">
        <color rgba="0.888 0.888 0.888 1.0" />
      </material>
    </visual>
    <visual>
      <origin xyz="0.0 0.0 0.0" rpy="0.0 0.0 0.0" />
      <geometry>
        <mesh filename="../meshes/f1_link/component_2.STL" />
      </geometry>
      <material name="Rubber_Textured">
        <color rgba="0.111 0.111 0.111 1.0" />
      </material>
    </visual>
    <visual>
      <origin xyz="0.0 0.0 0.0" rpy="0.0 0.0 0.0" />
      <geometry>
        <mesh filename="../meshes/f1_link/component_3.STL" />
      </geometry>
      <material name="Aluminum_Anodized">
        <color rgba="0.888 0.888 0.888 1.0" />
      </material>
    </visual>
    <collision>
      <origin xyz="-0.022 0.005 0.0" rpy="0.0 1.5708 0.0" />
      <geometry>
        <cylinder radius="0.011" length="0.014" />
      </geometry>
    </collision>
  </link>
  <joint name="f2" type="revolute">
    <origin xyz="-0.045 0.0 0.0" rpy="0.0 0.0 3.14159" />
    <parent link="f1_link" />
    <child link="f2_link" />
    <axis xyz="0.0 0.0 1.0" />
    <limit lower="0.0" upper="1.04719" effort="0.0" velocity="0.0" />
  </joint>
  <link name="f2_link">
    <inertial>
      <origin xyz="0.019715 -0.00463469 -0.000116042" rpy="0.0 0.0 0.0" />
      <mass value="0.0186424" />
      <inertia ixx="9.1068e-07" ixy="-1.35613e-07" ixz="-5.59275e-09" iyy="4.45508e-06" iyz="-7.10105e-09" izz="4.36492e-06" />
    </inertial>
    <visual>
      <origin xyz="0.0 0.0 0.0" rpy="0.0 0.0 0.0" />
      <geometry>
        <mesh filename="../meshes/f2_link/component_1.STL" />
      </geometry>
      <material name="Rubber_Textured">
        <color rgba="0.111 0.111 0.111 1.0" />
      </material>
    </visual>
    <visual>
      <origin xyz="0.0 0.0 0.0" rpy="0.0 0.0 0.0" />
      <geometry>
        <mesh filename="../meshes/f2_link/component_2.STL" />
      </geometry>
      <material name="Aluminum_Anodized">
        <color rgba="0.888 0.888 0.888 1.0" />
      </material>
    </visual>
    <visual>
      <origin xyz="0.0 0.0 0.0" rpy="0.0 0.0 0.0" />
      <geometry>
        <mesh filename="../meshes/f2_link/component_3.STL" />
      </geometry>
      <material name="Aluminum_Anodized">
        <color rgba="0.888 0.888 0.888 1.0" />
      </material>
    </visual>
    <collision>
      <origin xyz="0.0124972 -0.0024282 0.0" rpy="0.0 0.0 0.0" />
      <geometry>
        <sphere radius="0.009" />
      </geometry>
    </collision>
    <collision>
      <origin xyz="0.0365951 -0.00188703 0.0" rpy="0.0 0.0 0.0" />
      <geometry>
        <sphere radius="0.009" />
      </geometry>
    </collision>
  </link>
</robot>