<mujoco model="h1_description">
  <compiler angle="radian" meshdir="meshes/" autolimits="true" />
  <statistic meansize="0.219715" extent="1.9996" center="0.015564 2.74848e-06 -0.169929" />
  <asset>
    <mesh name="pelvis" file="pelvis.STL" />
    <mesh name="left_hip_yaw_link" file="left_hip_yaw_link.STL" />
    <mesh name="left_hip_roll_link" file="left_hip_roll_link.STL" />
    <mesh name="left_hip_pitch_link" file="left_hip_pitch_link.STL" />
    <mesh name="left_knee_link" file="left_knee_link.STL" />
    <mesh name="left_ankle_link" file="left_ankle_link.STL" />
    <mesh name="right_hip_yaw_link" file="right_hip_yaw_link.STL" />
    <mesh name="right_hip_roll_link" file="right_hip_roll_link.STL" />
    <mesh name="right_hip_pitch_link" file="right_hip_pitch_link.STL" />
    <mesh name="right_knee_link" file="right_knee_link.STL" />
    <mesh name="right_ankle_link" file="right_ankle_link.STL" />
    <mesh name="torso_link" file="torso_link.STL" />
    <mesh name="left_shoulder_pitch_link" file="left_shoulder_pitch_link.STL" />
    <mesh name="left_shoulder_roll_link" file="left_shoulder_roll_link.STL" />
    <mesh name="left_shoulder_yaw_link" file="left_shoulder_yaw_link.STL" />
    <mesh name="left_elbow_link" file="left_elbow_link.STL" />
    <mesh name="right_shoulder_pitch_link" file="right_shoulder_pitch_link.STL" />
    <mesh name="right_shoulder_roll_link" file="right_shoulder_roll_link.STL" />
    <mesh name="right_shoulder_yaw_link" file="right_shoulder_yaw_link.STL" />
    <mesh name="right_elbow_link" file="right_elbow_link.STL" />
    <mesh name="logo_link" file="logo_link.STL" />
    <texture type="skybox" builtin="gradient" rgb1=".4 .5 .6" rgb2="0 0 0" width="100" height="100"/>
    <texture builtin="flat" height="1278" mark="cross" markrgb="1 1 1" name="texgeom" random="0.01" rgb1="0.8 0.6 0.4" rgb2="0.8 0.6 0.4" type="cube" width="127"/>
    <texture builtin="checker" height="100" name="texplane" rgb1="0 0 0" rgb2="0.8 0.8 0.8" type="2d" width="100"/>
    <material name="MatPlane" reflectance="0.5" shininess="1" specular="1" texrepeat="60 60" texture="texplane"/>
    <material name="geom" texture="texgeom" texuniform="true"/>
  </asset>
  <worldbody>
    <light cutoff="100" diffuse="1 1 1" dir="-0 0 -1.3" directional="true" exponent="1" pos="0 0 1.3" specular=".1 .1 .1"/>
    <geom conaffinity="1" condim="3" name="floor" pos="0 0 0" rgba="0.8 0.9 0.8 1" size="100 100 .2" type="plane" material="MatPlane"/>
    <body name="pelvis" pos="0 0 1.1">
      <inertial pos="-0.0002 4e-05 -0.04522" quat="0.498303 0.499454 -0.500496 0.501741" mass="5.39"
        diaginertia="0.0490211 0.0445821 0.00824619" />
      <joint name="floating_base_joint" type="free" />
      <geom type="mesh" contype="0" conaffinity="0" group="1" density="0" rgba="0.1 0.1 0.1 1"
        mesh="pelvis" />
      <geom type="mesh" rgba="0.1 0.1 0.1 1" mesh="pelvis" />
      <body name="left_hip_yaw_link" pos="0 0.0875 -0.1742">
        <inertial pos="-0.04923 0.0001 0.0072" quat="0.69699 0.219193 0.233287 0.641667"
          mass="2.244" diaginertia="0.00304494 0.00296885 0.00189201" />
        <joint name="left_hip_yaw_joint" pos="0 0 0" axis="0 0 1" range="-0.43 0.43" />
        <geom type="mesh" contype="0" conaffinity="0" group="1" density="0" rgba="0.1 0.1 0.1 1"
          mesh="left_hip_yaw_link" />
        <geom size="0.06 0.035" pos="-0.067 0 0" quat="0.707123 0 0.70709 0" type="cylinder"
          rgba="0.1 0.1 0.1 1" />
        <body name="left_hip_roll_link" pos="0.039468 0 0">
          <inertial pos="-0.0058 -0.00319 -9e-05" quat="0.0438242 0.70721 -0.0729075 0.701867"
            mass="2.232" diaginertia="0.00243264 0.00225325 0.00205492" />
          <joint name="left_hip_roll_joint" pos="0 0 0" axis="1 0 0" range="-0.43 0.43" />
          <geom type="mesh" contype="0" conaffinity="0" group="1" density="0" rgba="0.1 0.1 0.1 1"
            mesh="left_hip_roll_link" />
          <geom type="mesh" rgba="0.1 0.1 0.1 1" mesh="left_hip_roll_link" />
          <body name="left_hip_pitch_link" pos="0 0.11536 0">
            <inertial pos="0.00746 -0.02346 -0.08193" quat="0.979828 0.0513522 -0.0169854 -0.192382"
              mass="4.152" diaginertia="0.0829503 0.0821457 0.00510909" />
            <joint name="left_hip_pitch_joint" pos="0 0 0" axis="0 1 0" range="-1.57 1.57" />
            <geom type="mesh" contype="0" conaffinity="0" group="1" density="0" rgba="0.1 0.1 0.1 1"
              mesh="left_hip_pitch_link" />
            <geom type="mesh" rgba="0.1 0.1 0.1 1" mesh="left_hip_pitch_link" />
            <body name="left_knee_link" pos="0 0 -0.4">
              <inertial pos="-0.00136 -0.00512 -0.1384"
                quat="0.626132 -0.034227 -0.0416277 0.777852" mass="1.721"
                diaginertia="0.0125237 0.0123104 0.0019428" />
              <joint name="left_knee_joint" pos="0 0 0" axis="0 1 0" range="-0.26 2.05" />
              <geom type="mesh" contype="0" conaffinity="0" group="1" density="0"
                rgba="0.1 0.1 0.1 1" mesh="left_knee_link" />
              <geom type="mesh" rgba="0.1 0.1 0.1 1" mesh="left_knee_link" />
              <body name="left_ankle_link" pos="0 0 -0.4">
                <inertial pos="0.06722 0.00015 -0.04497" quat="0.489101 0.503197 0.565782 0.432972"
                  mass="0.446" diaginertia="0.00220848 0.00218961 0.000214202" />
                <joint name="left_ankle_joint" pos="0 0 0" axis="0 1 0" range="-0.87 0.52" />
                <geom type="mesh" contype="0" conaffinity="0" group="1" density="0"
                  rgba="0.1 0.1 0.1 1" mesh="left_ankle_link" />
                <geom type="mesh" rgba="0.1 0.1 0.1 1" mesh="left_ankle_link" />
              </body>
            </body>
          </body>
        </body>
      </body>
      <body name="right_hip_yaw_link" pos="0 -0.0875 -0.1742">
        <inertial pos="-0.04923 -0.0001 0.0072" quat="0.641667 0.233287 0.219193 0.69699"
          mass="2.244" diaginertia="0.00304494 0.00296885 0.00189201" />
        <joint name="right_hip_yaw_joint" pos="0 0 0" axis="0 0 1" range="-0.43 0.43" />
        <geom type="mesh" contype="0" conaffinity="0" group="1" density="0" rgba="0.1 0.1 0.1 1"
          mesh="right_hip_yaw_link" />
        <geom size="0.06 0.035" pos="-0.067 0 0" quat="0.707123 0 0.70709 0" type="cylinder"
          rgba="0.1 0.1 0.1 1" />
        <body name="right_hip_roll_link" pos="0.039468 0 0">
          <inertial pos="-0.0058 0.00319 -9e-05" quat="-0.0438242 0.70721 0.0729075 0.701867"
            mass="2.232" diaginertia="0.00243264 0.00225325 0.00205492" />
          <joint name="right_hip_roll_joint" pos="0 0 0" axis="1 0 0" range="-0.43 0.43" />
          <geom type="mesh" contype="0" conaffinity="0" group="1" density="0" rgba="0.1 0.1 0.1 1"
            mesh="right_hip_roll_link" />
          <geom type="mesh" rgba="0.1 0.1 0.1 1" mesh="right_hip_roll_link" />
          <body name="right_hip_pitch_link" pos="0 -0.11536 0">
            <inertial pos="0.00746 0.02346 -0.08193" quat="0.979828 -0.0513522 -0.0169854 0.192382"
              mass="4.152" diaginertia="0.0829503 0.0821457 0.00510909" />
            <joint name="right_hip_pitch_joint" pos="0 0 0" axis="0 1 0" range="-1.57 1.57" />
            <geom type="mesh" contype="0" conaffinity="0" group="1" density="0" rgba="0.1 0.1 0.1 1"
              mesh="right_hip_pitch_link" />
            <geom type="mesh" rgba="0.1 0.1 0.1 1" mesh="right_hip_pitch_link" />
            <body name="right_knee_link" pos="0 0 -0.4">
              <inertial pos="-0.00136 0.00512 -0.1384" quat="0.777852 -0.0416277 -0.034227 0.626132"
                mass="1.721" diaginertia="0.0125237 0.0123104 0.0019428" />
              <joint name="right_knee_joint" pos="0 0 0" axis="0 1 0" range="-0.26 2.05" />
              <geom type="mesh" contype="0" conaffinity="0" group="1" density="0"
                rgba="0.1 0.1 0.1 1" mesh="right_knee_link" />
              <geom type="mesh" rgba="0.1 0.1 0.1 1" mesh="right_knee_link" />
              <body name="right_ankle_link" pos="0 0 -0.4">
                <inertial pos="0.06722 -0.00015 -0.04497" quat="0.432972 0.565782 0.503197 0.489101"
                  mass="0.446" diaginertia="0.00220848 0.00218961 0.000214202" />
                <joint name="right_ankle_joint" pos="0 0 0" axis="0 1 0" range="-0.87 0.52" />
                <geom type="mesh" contype="0" conaffinity="0" group="1" density="0"
                  rgba="0.1 0.1 0.1 1" mesh="right_ankle_link" />
                <geom type="mesh" rgba="0.1 0.1 0.1 1" mesh="right_ankle_link" />
              </body>
            </body>
          </body>
        </body>
      </body>
      <body name="torso_link">
        <inertial pos="0.000489 0.002797 0.20484"
          quat="0.999989 -0.00130808 -0.00282289 -0.00349105" mass="17.789"
          diaginertia="0.487315 0.409628 0.127837" />
        <joint name="torso_joint" pos="0 0 0" axis="0 0 1" range="-2.35 2.35" />
        <geom type="mesh" contype="0" conaffinity="0" group="1" density="0" rgba="0.1 0.1 0.1 1"
          mesh="torso_link" />
        <geom type="mesh" rgba="0.1 0.1 0.1 1" mesh="torso_link" />
        <geom type="mesh" contype="0" conaffinity="0" group="1" density="0" rgba="1 1 1 1"
          mesh="logo_link" />
        <site name="imu" size="0.01" pos="-0.04452 -0.01891 0.27756" />
        <body name="left_shoulder_pitch_link" pos="0.0055 0.15535 0.42999"
          quat="0.976296 0.216438 0 0">
          <inertial pos="0.005045 0.053657 -0.015715"
            quat="0.814858 0.579236 -0.0201072 -0.00936488" mass="1.033"
            diaginertia="0.00129936 0.000987113 0.000858198" />
          <joint name="left_shoulder_pitch_joint" pos="0 0 0" axis="0 1 0" range="-2.87 2.87" />
          <geom type="mesh" contype="0" conaffinity="0" group="1" density="0" rgba="0.1 0.1 0.1 1"
            mesh="left_shoulder_pitch_link" />
          <geom type="mesh" rgba="0.1 0.1 0.1 1" mesh="left_shoulder_pitch_link" />
          <body name="left_shoulder_roll_link" pos="-0.0055 0.0565 -0.0165"
            quat="0.976296 -0.216438 0 0">
            <inertial pos="0.000679 0.00115 -0.094076" quat="0.732491 0.00917179 0.0766656 0.676384"
              mass="0.793" diaginertia="0.00170388 0.00158256 0.00100336" />
            <joint name="left_shoulder_roll_joint" pos="0 0 0" axis="1 0 0" range="-0.34 3.11" />
            <geom type="mesh" contype="0" conaffinity="0" group="1" density="0" rgba="0.1 0.1 0.1 1"
              mesh="left_shoulder_roll_link" />
            <geom type="mesh" rgba="0.1 0.1 0.1 1" mesh="left_shoulder_roll_link" />
            <body name="left_shoulder_yaw_link" pos="0 0 -0.1343">
              <inertial pos="0.01365 0.002767 -0.16266"
                quat="0.703042 -0.0331229 -0.0473362 0.708798" mass="0.839"
                diaginertia="0.00408038 0.00370367 0.000622687" />
              <joint name="left_shoulder_yaw_joint" pos="0 0 0" axis="0 0 1" range="-1.3 4.45" />
              <geom type="mesh" contype="0" conaffinity="0" group="1" density="0"
                rgba="0.1 0.1 0.1 1" mesh="left_shoulder_yaw_link" />
              <geom type="mesh" rgba="0.1 0.1 0.1 1" mesh="left_shoulder_yaw_link" />
              <body name="left_elbow_link" pos="0.0185 0 -0.198">
                <inertial pos="0.15908 -0.000144 -0.015776"
                  quat="0.0765232 0.720327 0.0853116 0.684102" mass="0.669"
                  diaginertia="0.00601829 0.00600579 0.000408305" />
                <joint name="left_elbow_joint" pos="0 0 0" axis="0 1 0" range="-1.25 2.61" />
                <geom type="mesh" contype="0" conaffinity="0" group="1" density="0"
                  rgba="0.1 0.1 0.1 1" mesh="left_elbow_link" />
                <geom type="mesh" rgba="0.1 0.1 0.1 1" mesh="left_elbow_link" />
              </body>
            </body>
          </body>
        </body>
        <body name="right_shoulder_pitch_link" pos="0.0055 -0.15535 0.42999" quat="0.976296 -0.216438 0 0">
          <inertial pos="0.005045 -0.053657 -0.015715" quat="0.579236 0.814858 0.00936488 0.0201072"
            mass="1.033" diaginertia="0.00129936 0.000987113 0.000858198" />
          <joint name="right_shoulder_pitch_joint" pos="0 0 0" axis="0 1 0" range="-2.87 2.87" />
          <geom type="mesh" contype="0" conaffinity="0" group="1" density="0" rgba="0.1 0.1 0.1 1"
            mesh="right_shoulder_pitch_link" />
          <geom type="mesh" rgba="0.1 0.1 0.1 1" mesh="right_shoulder_pitch_link" />
          <body name="right_shoulder_roll_link" pos="-0.0055 -0.0565 -0.0165"
            quat="0.976296 0.216438 0 0">
            <inertial pos="0.000679 -0.00115 -0.094076"
              quat="0.676384 0.0766656 0.00917179 0.732491" mass="0.793"
              diaginertia="0.00170388 0.00158256 0.00100336" />
            <joint name="right_shoulder_roll_joint" pos="0 0 0" axis="1 0 0" range="-3.11 0.34" />
            <geom type="mesh" contype="0" conaffinity="0" group="1" density="0" rgba="0.1 0.1 0.1 1"
              mesh="right_shoulder_roll_link" />
            <geom type="mesh" rgba="0.1 0.1 0.1 1" mesh="right_shoulder_roll_link" />
            <body name="right_shoulder_yaw_link" pos="0 0 -0.1343">
              <inertial pos="0.01365 -0.002767 -0.16266"
                quat="0.708798 -0.0473362 -0.0331229 0.703042" mass="0.839"
                diaginertia="0.00408038 0.00370367 0.000622687" />
              <joint name="right_shoulder_yaw_joint" pos="0 0 0" axis="0 0 1" range="-4.45 1.3" />
              <geom type="mesh" contype="0" conaffinity="0" group="1" density="0"
                rgba="0.1 0.1 0.1 1" mesh="right_shoulder_yaw_link" />
              <geom type="mesh" rgba="0.1 0.1 0.1 1" mesh="right_shoulder_yaw_link" />
              <body name="right_elbow_link" pos="0.0185 0 -0.198">
                <inertial pos="0.15908 0.000144 -0.015776"
                  quat="-0.0765232 0.720327 -0.0853116 0.684102" mass="0.669"
                  diaginertia="0.00601829 0.00600579 0.000408305" />
                <joint name="right_elbow_joint" pos="0 0 0" axis="0 1 0" range="-1.25 2.61" />
                <geom type="mesh" contype="0" conaffinity="0" group="1" density="0"
                  rgba="0.1 0.1 0.1 1" mesh="right_elbow_link" />
                <geom type="mesh" rgba="0.1 0.1 0.1 1" mesh="right_elbow_link" />
              </body>
            </body>
          </body>
        </body>
      </body>
    </body>
  </worldbody>

  <actuator>
    <position name="left_hip_yaw_joint" joint="left_hip_yaw_joint" />
    <position name="left_hip_roll_joint" joint="left_hip_roll_joint" />
    <position name="left_hip_pitch_joint" joint="left_hip_pitch_joint" />
    <position name="left_knee_joint" joint="left_knee_joint" />
    <position name="left_ankle_joint" joint="left_ankle_joint" />
    <position name="right_hip_yaw_joint" joint="right_hip_yaw_joint" />
    <position name="right_hip_roll_joint" joint="right_hip_roll_joint" />
    <position name="right_hip_pitch_joint" joint="right_hip_pitch_joint" />
    <position name="right_knee_joint" joint="right_knee_joint" />
    <position name="right_ankle_joint" joint="right_ankle_joint" />
    <position name="torso_joint" joint="torso_joint" />
    <position name="left_shoulder_pitch_joint" joint="left_shoulder_pitch_joint" />
    <position name="left_shoulder_roll_joint" joint="left_shoulder_roll_joint" />
    <position name="left_shoulder_yaw_joint" joint="left_shoulder_yaw_joint" />
    <position name="left_elbow_joint" joint="left_elbow_joint" />
    <position name="right_shoulder_pitch_joint" joint="right_shoulder_pitch_joint" />
    <position name="right_shoulder_roll_joint" joint="right_shoulder_roll_joint" />
    <position name="right_shoulder_yaw_joint" joint="right_shoulder_yaw_joint" />
    <position name="right_elbow_joint" joint="right_elbow_joint" />
  </actuator>

  <sensor>
    <gyro name="imu-angular-velocity" site="imu" noise="5e-4" cutoff="34.9" />
    <accelerometer name="imu-linear-acceleration" site="imu" noise="1e-2" cutoff="157" />
  </sensor>

  <keyframe>
    <key name="home"
      qpos="0 0 0.98 1 0 0 0 0 0 -0.4 0.8 -0.4 0 0 -0.4 0.8 -0.4 0 0 0 0 0 0 0 0 0" />
  </keyframe>
</mujoco>