<?xml version="1.0" encoding="utf-8"?>
<!-- Mentee Robotics LTD -->
<robot name="robot">
  <link name="pelvis">
    <inertial>
      <origin xyz="-1.25741e-07 -1.33454e-07 0.0152498" rpy="0.0 0.0 0.0" />
      <mass value="3.87326" />
      <inertia ixx="0.0435714" ixy="-4.86896e-05" ixz="2.87098e-08" iyy="0.00555697" iyz="2.90504e-08" izz="0.0431398" />
    </inertial>
    <visual>
      <origin xyz="0.0 0.0 0.0" rpy="0.0 0.0 0.0" />
      <geometry>
        <mesh filename="../meshes/pelvis.STL" />
      </geometry>
      <material name="pelvis_material">
        <color rgba="0.2 0.4 0.7 1.0" />
      </material>
    </visual>
  </link>
  <joint name="left_hip_yaw" type="revolute">
    <origin xyz="0.0 0.1065 -0.1079" rpy="-3.14159 0.0 1.5708" />
    <parent link="pelvis" />
    <child link="left_hip_yaw" />
    <axis xyz="0.0 0.0 1.0" />
    <limit lower="-0.51" upper="0.34" effort="80.0" velocity="5.0" />
  </joint>
  <link name="left_hip_yaw">
    <inertial>
      <origin xyz="2.04512e-05 -0.0454981 -0.044589" rpy="0.0 0.0 0.0" />
      <mass value="2.21393" />
      <inertia ixx="0.0128772" ixy="3.52268e-06" ixz="-1.92609e-06" iyy="0.00632561" iyz="0.00313832" izz="0.00842695" />
    </inertial>
    <visual>
      <origin xyz="0.0 0.0 0.0" rpy="0.0 0.0 0.0" />
      <geometry>
        <mesh filename="../meshes/left_hip_yaw.STL" />
      </geometry>
      <material name="left_hip_yaw_material">
        <color rgba="0.2 0.2 0.2 1.0" />
      </material>
    </visual>
    <collision>
      <origin xyz="0.0 -0.03 0.0" rpy="1.5708 0.0 0.0" />
      <geometry>
        <cylinder radius="0.05" length="0.12" />
      </geometry>
    </collision>
  </link>
  <joint name="left_hip_roll" type="revolute">
    <origin xyz="0.0 0.0 0.0" rpy="-1.5708 0.0 0.0" />
    <parent link="left_hip_yaw" />
    <child link="left_hip_roll" />
    <axis xyz="0.0 0.0 1.0" />
    <limit lower="-1.0" upper="1.55" effort="80.0" velocity="5.0" />
  </joint>
  <link name="left_hip_roll">
    <inertial>
      <origin xyz="0.00414627 0.000443354 -0.00202141" rpy="0.0 0.0 0.0" />
      <mass value="1.6064" />
      <inertia ixx="0.00351526" ixy="-1.92662e-05" ixz="-2.25795e-05" iyy="0.00329217" iyz="4.10917e-06" izz="0.00138413" />
    </inertial>
    <visual>
      <origin xyz="0.0 0.0 0.0" rpy="0.0 0.0 0.0" />
      <geometry>
        <mesh filename="../meshes/left_hip_roll.STL" />
      </geometry>
      <material name="left_hip_roll_material">
        <color rgba="0.25 0.25 0.25 1.0" />
      </material>
    </visual>
  </link>
  <joint name="left_hip_pitch" type="revolute">
    <origin xyz="0.0 0.0 0.0" rpy="-1.5708 0.0 1.5708" />
    <parent link="left_hip_roll" />
    <child link="left_hip_pitch" />
    <axis xyz="0.0 0.0 1.0" />
    <limit lower="-0.6" upper="2.0" effort="80.0" velocity="5.0" />
  </joint>
  <link name="left_hip_pitch">
    <inertial>
      <origin xyz="-0.0570049 1.37902e-08 -0.00427395" rpy="0.0 0.0 0.0" />
      <mass value="0.386792" />
      <inertia ixx="0.000499941" ixy="-7.56077e-11" ixz="-0.000105156" iyy="0.00139585" iyz="-3.0708e-10" izz="0.00100934" />
    </inertial>
    <visual>
      <origin xyz="0.0 0.0 0.0" rpy="0.0 0.0 0.0" />
      <geometry>
        <mesh filename="../meshes/left_hip_pitch.STL" />
      </geometry>
      <material name="left_hip_pitch_material">
        <color rgba="0.2 0.4 0.7 1.0" />
      </material>
    </visual>
    <collision>
      <origin xyz="-0.26 0.0 0.0" rpy="0.0 1.5708 0.0" />
      <geometry>
        <cylinder radius="0.04" length="0.18" />
      </geometry>
    </collision>
  </link>
  <joint name="left_leg_ee" type="fixed">
    <origin xyz="-0.114 0.0 -0.0025" rpy="0.0 0.0 0.0" />
    <parent link="left_hip_pitch" />
    <child link="left_leg_ee_link" />
  </joint>
  <link name="left_leg_ee_link" />
  <joint name="right_hip_yaw" type="revolute">
    <origin xyz="0.0 -0.1065 -0.1079" rpy="3.1416 0.0 -1.5708" />
    <parent link="pelvis" />
    <child link="right_hip_yaw" />
    <axis xyz="0.0 0.0 1.0" />
    <limit lower="-0.34" upper="0.51" effort="80.0" velocity="5.0" />
  </joint>
  <link name="right_hip_yaw">
    <inertial>
      <origin xyz="-2.04512e-05 0.0454981 -0.044589" rpy="0.0 0.0 0.0" />
      <mass value="2.21393" />
      <inertia ixx="0.0128772" ixy="3.52268e-06" ixz="1.92609e-06" iyy="0.00632561" iyz="-0.00313832" izz="0.00842695" />
    </inertial>
    <visual>
      <origin xyz="0.0 0.0 0.0" rpy="0.0 0.0 0.0" />
      <geometry>
        <mesh filename="../meshes/right_hip_yaw.STL" />
      </geometry>
      <material name="right_hip_yaw_material">
        <color rgba="0.2 0.2 0.2 1.0" />
      </material>
    </visual>
    <collision>
      <origin xyz="0.0 0.03 0.0" rpy="1.5708 0.0 0.0" />
      <geometry>
        <cylinder radius="0.05" length="0.12" />
      </geometry>
    </collision>
  </link>
  <joint name="right_hip_roll" type="revolute">
    <origin xyz="0.0 0.0 0.0" rpy="-1.5708 0.0 3.1416" />
    <parent link="right_hip_yaw" />
    <child link="right_hip_roll" />
    <axis xyz="0.0 0.0 1.0" />
    <limit lower="-1.55" upper="1.0" effort="80.0" velocity="5.0" />
  </joint>
  <link name="right_hip_roll">
    <inertial>
      <origin xyz="-0.00414627 0.000443354 -0.00238456" rpy="0.0 0.0 0.0" />
      <mass value="1.6064" />
      <inertia ixx="0.00351269" ixy="1.92662e-05" ixz="6.76678e-06" iyy="0.0032896" iyz="-7.24713e-06" izz="0.00138413" />
    </inertial>
    <visual>
      <origin xyz="0.0 0.0 0.0" rpy="0.0 0.0 0.0" />
      <geometry>
        <mesh filename="../meshes/right_hip_roll.STL" />
      </geometry>
      <material name="right_hip_roll_material">
        <color rgba="0.25 0.25 0.25 1.0" />
      </material>
    </visual>
  </link>
  <joint name="right_hip_pitch" type="revolute">
    <origin xyz="0.0 0.0 0.0" rpy="-1.5708 0.0 -1.5708" />
    <parent link="right_hip_roll" />
    <child link="right_hip_pitch" />
    <axis xyz="0.0 0.0 1.0" />
    <limit lower="-2.0" upper="0.6" effort="80.0" velocity="5.0" />
  </joint>
  <link name="right_hip_pitch">
    <inertial>
      <origin xyz="0.0570049 -1.37908e-08 -0.00427395" rpy="0.0 0.0 0.0" />
      <mass value="0.386792" />
      <inertia ixx="0.000499941" ixy="-7.56087e-11" ixz="0.000105156" iyy="0.00139585" iyz="3.07082e-10" izz="0.00100934" />
    </inertial>
    <visual>
      <origin xyz="0.0 0.0 0.0" rpy="0.0 0.0 0.0" />
      <geometry>
        <mesh filename="../meshes/right_hip_pitch.STL" />
      </geometry>
      <material name="right_hip_pitch_material">
        <color rgba="0.2 0.4 0.7 1.0" />
      </material>
    </visual>
    <collision>
      <origin xyz="0.26 0.0 0.0" rpy="0.0 1.5708 0.0" />
      <geometry>
        <cylinder radius="0.04" length="0.18" />
      </geometry>
    </collision>
  </link>
  <joint name="right_leg_ee" type="fixed">
    <origin xyz="0.114 0.0 -0.0025" rpy="0.0 0.0 0.0" />
    <parent link="right_hip_pitch" />
    <child link="right_leg_ee_link" />
  </joint>
  <link name="right_leg_ee_link" />
</robot>