<?xml version="1.0" encoding="utf-8"?>
<!-- Mentee Robotics LTD -->
<robot name="robot">
  <link name="base_link">
    <inertial>
      <origin xyz="-0.0276412 0.000163302 0.0674305" rpy="0.0 0.0 0.0" />
      <mass value="4.97822" />
      <inertia ixx="0.011587" ixy="1.08017e-05" ixz="0.000423949" iyy="0.0108768" iyz="-1.16909e-05" izz="0.0160386" />
    </inertial>
    <visual>
      <origin xyz="0.0 0.0 0.0" rpy="0.0 0.0 0.0" />
      <geometry>
        <mesh filename="../meshes/base_link/component_13_22-32-101-30.STL" />
      </geometry>
      <material name="Aluminum_Cast">
        <color rgba="0.555 0.555 0.555 1.0" />
      </material>
    </visual>
    <visual>
      <origin xyz="0.0 0.0 0.0" rpy="0.0 0.0 0.0" />
      <geometry>
        <mesh filename="../meshes/base_link/component_14_22-32-101-21.STL" />
      </geometry>
      <material name="Aluminum_Cast">
        <color rgba="0.555 0.555 0.555 1.0" />
      </material>
    </visual>
    <visual>
      <origin xyz="0.0 0.0 0.0" rpy="0.0 0.0 0.0" />
      <geometry>
        <mesh filename="../meshes/base_link/component_17_22-32-101-631.STL" />
      </geometry>
      <material name="Aluminum_Cast">
        <color rgba="0.555 0.555 0.555 1.0" />
      </material>
    </visual>
    <visual>
      <origin xyz="0.0 0.0 0.0" rpy="0.0 0.0 0.0" />
      <geometry>
        <mesh filename="../meshes/base_link/component_18_22-32-101-208.STL" />
      </geometry>
      <material name="MI_WhitePlastic">
        <color rgba="0.888 0.888 0.888 1.0" />
      </material>
    </visual>
    <collision>
      <origin xyz="-0.0234 0.0 0.0502825" rpy="0.0 0.0 0.0" />
      <geometry>
        <sphere radius="0.075" />
      </geometry>
    </collision>
  </link>
  <joint name="center_ee" type="fixed">
    <origin xyz="0.052483 0.0 0.06129" rpy="0.0 0.0 0.0" />
    <parent link="base_link" />
    <child link="center_ee" />
  </joint>
  <link name="center_ee" />
  <joint name="imu_pelvis" type="fixed">
    <origin xyz="0.0 0.0 0.0" rpy="0.0 0.0 0.0" />
    <parent link="base_link" />
    <child link="imu_pelvis" />
  </joint>
  <link name="imu_pelvis">
    <inertial>
      <origin xyz="-0.00564954 -0.0076969 0.00128756" rpy="0.0 0.0 0.0" />
      <mass value="0.0102286" />
      <inertia ixx="9.63262e-07" ixy="-1.77855e-10" ixz="3.76127e-08" iyy="7.46825e-07" iyz="4.92881e-11" izz="1.45547e-06" />
    </inertial>
  </link>
  <joint name="left_leg_ee" type="fixed">
    <origin xyz="-0.0273 0.083309 0.039036" rpy="0.0 0.0 0.0" />
    <parent link="base_link" />
    <child link="left_leg_ee_link" />
  </joint>
  <link name="left_leg_ee_link" />
  <joint name="right_leg_ee" type="fixed">
    <origin xyz="-0.0273 -0.083309 0.039036" rpy="0.0 0.0 0.0" />
    <parent link="base_link" />
    <child link="right_leg_ee_link" />
  </joint>
  <link name="right_leg_ee_link" />
  <joint name="torso_yaw" type="revolute">
    <origin xyz="-0.0273 0.0 0.16379" rpy="0.0 0.0 3.1416" />
    <parent link="base_link" />
    <child link="torso_yaw_link" />
    <axis xyz="0.0 0.0 1.0" />
    <limit lower="-0.785" upper="0.785" effort="149.0" velocity="5.9" />
  </joint>
  <link name="torso_yaw_link">
    <inertial>
      <origin xyz="0.0153412 1.57646e-05 -0.0299229" rpy="0.0 0.0 0.0" />
      <mass value="0.924565" />
      <inertia ixx="0.00102871" ixy="-2.94902e-08" ixz="-5.38851e-05" iyy="0.00210192" iyz="4.38441e-07" izz="0.00198172" />
    </inertial>
    <visual>
      <origin xyz="0.0 0.0 0.0" rpy="0.0 0.0 0.0" />
      <geometry>
        <mesh filename="../meshes/torso_yaw_link/component_0_22-32-101-78-103.STL" />
      </geometry>
      <material name="Aluminum_Cast">
        <color rgba="0.555 0.555 0.555 1.0" />
      </material>
    </visual>
    <visual>
      <origin xyz="0.0 0.0 0.0" rpy="0.0 0.0 0.0" />
      <geometry>
        <mesh filename="../meshes/torso_yaw_link/component_1_22-32-101-78-186.STL" />
      </geometry>
      <material name="Aluminum_Cast">
        <color rgba="0.555 0.555 0.555 1.0" />
      </material>
    </visual>
    <visual>
      <origin xyz="0.0 0.0 0.0" rpy="0.0 0.0 0.0" />
      <geometry>
        <mesh filename="../meshes/torso_yaw_link/component_10_22-32-153.STL" />
      </geometry>
      <material name="Aluminum_Cast">
        <color rgba="0.555 0.555 0.555 1.0" />
      </material>
    </visual>
    <visual>
      <origin xyz="0.0 0.0 0.0" rpy="0.0 0.0 0.0" />
      <geometry>
        <mesh filename="../meshes/torso_yaw_link/component_2_22-32-159.STL" />
      </geometry>
      <material name="Aluminum_Cast">
        <color rgba="0.555 0.555 0.555 1.0" />
      </material>
    </visual>
    <visual>
      <origin xyz="0.0 0.0 0.0" rpy="0.0 0.0 0.0" />
      <geometry>
        <mesh filename="../meshes/torso_yaw_link/component_3_22-32-101-78-236.STL" />
      </geometry>
      <material name="Aluminum_Cast">
        <color rgba="0.555 0.555 0.555 1.0" />
      </material>
    </visual>
    <visual>
      <origin xyz="0.0 0.0 0.0" rpy="0.0 0.0 0.0" />
      <geometry>
        <mesh filename="../meshes/torso_yaw_link/component_4_22-32-101-78-235.STL" />
      </geometry>
      <material name="Aluminum_Cast">
        <color rgba="0.555 0.555 0.555 1.0" />
      </material>
    </visual>
    <visual>
      <origin xyz="0.0 0.0 0.0" rpy="0.0 0.0 0.0" />
      <geometry>
        <mesh filename="../meshes/torso_yaw_link/component_7_22-32-101-78-245.STL" />
      </geometry>
      <material name="Aluminum_Cast">
        <color rgba="0.555 0.555 0.555 1.0" />
      </material>
    </visual>
    <visual>
      <origin xyz="0.0 0.0 0.0" rpy="0.0 0.0 0.0" />
      <geometry>
        <mesh filename="../meshes/torso_yaw_link/component_8_22-32-101-78-220.STL" />
      </geometry>
      <material name="Aluminum_Cast">
        <color rgba="0.555 0.555 0.555 1.0" />
      </material>
    </visual>
    <visual>
      <origin xyz="0.0 0.0 0.0" rpy="0.0 0.0 0.0" />
      <geometry>
        <mesh filename="../meshes/torso_yaw_link/component_9_22-32-101-78-23.STL" />
      </geometry>
      <material name="Aluminum_Cast">
        <color rgba="0.555 0.555 0.555 1.0" />
      </material>
    </visual>
  </link>
  <joint name="left_link1_ee" type="fixed">
    <origin xyz="0.075 -0.0365 -0.02" rpy="1.5708 1.5708 0.0" />
    <parent link="torso_yaw_link" />
    <child link="left_link1_ee" />
  </joint>
  <link name="left_link1_ee" />
  <joint name="right_link1_ee" type="fixed">
    <origin xyz="0.075 0.0365 -0.02" rpy="1.5708 1.5708 0.0" />
    <parent link="torso_yaw_link" />
    <child link="right_link1_ee" />
  </joint>
  <link name="right_link1_ee" />
  <joint name="torso_pitch" type="revolute">
    <origin xyz="0.0 0.0 0.0" rpy="-1.5708 0.0 -3.14159" />
    <parent link="torso_yaw_link" />
    <child link="torso_pitch_link" />
    <axis xyz="0.0 0.0 -1.0" />
    <limit lower="-0.26" upper="0.79" effort="0.0" velocity="0.0" />
  </joint>
  <link name="torso_pitch_link">
    <inertial>
      <origin xyz="-1.68688e-07 1.27546e-09 -1.34191e-08" rpy="0.0 0.0 0.0" />
      <mass value="0.151575" />
      <inertia ixx="3.09164e-05" ixy="-4.39002e-10" ixz="-2.56572e-10" iyy="5.49713e-05" iyz="1.13278e-11" izz="3.09182e-05" />
    </inertial>
    <visual>
      <origin xyz="0.0 0.0 0.0" rpy="0.0 0.0 0.0" />
      <geometry>
        <mesh filename="../meshes/torso_pitch_link/component_0_22-32-101-78-281.STL" />
      </geometry>
      <material name="Aluminum_Cast">
        <color rgba="0.555 0.555 0.555 1.0" />
      </material>
    </visual>
  </link>
  <joint name="torso_roll" type="revolute">
    <origin xyz="0.0 0.0 0.0" rpy="-1.5708 0.0 -1.5708" />
    <parent link="torso_pitch_link" />
    <child link="torso_roll" />
    <axis xyz="0.0 0.0 1.0" />
    <limit lower="-0.27" upper="0.27" effort="0.0" velocity="0.0" />
  </joint>
  <link name="torso_roll">
    <inertial>
      <origin xyz="0.187546 0.00124312 -0.00943038" rpy="0.0 0.0 0.0" />
      <mass value="22.5979" />
      <inertia ixx="0.230652" ixy="0.00086874" ixz="0.00744314" iyy="0.646461" iyz="0.00144015" izz="0.605789" />
    </inertial>
    <visual>
      <origin xyz="0.0 0.0 0.0" rpy="0.0 0.0 0.0" />
      <geometry>
        <mesh filename="../meshes/torso_roll/component_7_22-133-298.STL" />
      </geometry>
      <material name="Aluminum_Cast">
        <color rgba="0.555 0.555 0.555 1.0" />
      </material>
    </visual>
    <visual>
      <origin xyz="0.0 0.0 0.0" rpy="0.0 0.0 0.0" />
      <geometry>
        <mesh filename="../meshes/torso_roll/component_8_22-74-219.STL" />
      </geometry>
      <material name="Plastic_ABS">
        <color rgba="0.222 0.222 0.222 1.0" />
      </material>
    </visual>
    <visual>
      <origin xyz="0.0 0.0 0.0" rpy="0.0 0.0 0.0" />
      <geometry>
        <mesh filename="../meshes/torso_roll/component_10_22-23-1598-21.STL" />
      </geometry>
      <material name="Plastic_ABS">
        <color rgba="0.222 0.222 0.222 1.0" />
      </material>
    </visual>
    <visual>
      <origin xyz="0.0 0.0 0.0" rpy="0.0 0.0 0.0" />
      <geometry>
        <mesh filename="../meshes/torso_roll/component_11_22-23-1599-21.STL" />
      </geometry>
      <material name="Plastic_ABS">
        <color rgba="0.222 0.222 0.222 1.0" />
      </material>
    </visual>
    <visual>
      <origin xyz="0.0 0.0 0.0" rpy="0.0 0.0 0.0" />
      <geometry>
        <mesh filename="../meshes/torso_roll/component_12_22-74-1085-21.STL" />
      </geometry>
      <material name="Plastic_ABS">
        <color rgba="0.222 0.222 0.222 1.0" />
      </material>
    </visual>
    <visual>
      <origin xyz="0.0 0.0 0.0" rpy="0.0 0.0 0.0" />
      <geometry>
        <mesh filename="../meshes/torso_roll/component_23_22-25-1061-22.STL" />
      </geometry>
      <material name="Plastic_ABS">
        <color rgba="0.222 0.222 0.222 1.0" />
      </material>
    </visual>
    <visual>
      <origin xyz="0.0 0.0 0.0" rpy="0.0 0.0 0.0" />
      <geometry>
        <mesh filename="../meshes/torso_roll/component_4_22-133-828-28.STL" />
      </geometry>
      <material name="MI_WhitePlastic">
        <color rgba="0.888 0.888 0.888 1.0" />
      </material>
    </visual>
    <visual>
      <origin xyz="0.0 0.0 0.0" rpy="0.0 0.0 0.0" />
      <geometry>
        <mesh filename="../meshes/torso_roll/component_6_22-133-542.STL" />
      </geometry>
      <material name="MI_WhitePlastic">
        <color rgba="0.888 0.888 0.888 1.0" />
      </material>
    </visual>
    <visual>
      <origin xyz="0.0 0.0 0.0" rpy="0.0 0.0 0.0" />
      <geometry>
        <mesh filename="../meshes/torso_roll/component_18_22-133-315.STL" />
      </geometry>
      <material name="MI_WhitePlastic">
        <color rgba="0.888 0.888 0.888 1.0" />
      </material>
    </visual>
    <visual>
      <origin xyz="0.0 0.0 0.0" rpy="0.0 0.0 0.0" />
      <geometry>
        <mesh filename="../meshes/torso_roll/component_13_22-805.STL" />
      </geometry>
      <material name="MI_WhitePlastic">
        <color rgba="0.888 0.888 0.888 1.0" />
      </material>
    </visual>
    <visual>
      <origin xyz="0.0 0.0 0.0" rpy="0.0 0.0 0.0" />
      <geometry>
        <mesh filename="../meshes/torso_roll/component_19_22-808.STL" />
      </geometry>
      <material name="MI_WhitePlastic">
        <color rgba="0.888 0.888 0.888 1.0" />
      </material>
    </visual>
    <visual>
      <origin xyz="0.0 0.0 0.0" rpy="0.0 0.0 0.0" />
      <geometry>
        <mesh filename="../meshes/torso_roll/component_21_22-133-885.STL" />
      </geometry>
      <material name="Clear_Glass">
        <color rgba="0.988 0.988 0.988 0.1" />
      </material>
    </visual>
    <visual>
      <origin xyz="0.0 0.0 0.0" rpy="0.0 0.0 0.0" />
      <geometry>
        <mesh filename="../meshes/torso_roll/component_20_22-133-884.STL" />
      </geometry>
      <material name="Aluminum_Anodized_Black">
        <color rgba="0.112 0.112 0.112 1.0" />
      </material>
    </visual>
    <visual>
      <origin xyz="0.0 0.0 0.0" rpy="0.0 0.0 0.0" />
      <geometry>
        <mesh filename="../meshes/torso_roll/component_9_22-74-394.STL" />
      </geometry>
      <material name="Aluminum_Anodized_Black">
        <color rgba="0.112 0.112 0.112 1.0" />
      </material>
    </visual>
    <visual>
      <origin xyz="0.0 0.0 0.0" rpy="0.0 0.0 0.0" />
      <geometry>
        <mesh filename="../meshes/torso_roll/component_5_22-133-295.STL" />
      </geometry>
      <material name="Polymethylmethacrylate_Clear">
        <color rgba="0.333 0.333 0.333 0.5" />
      </material>
    </visual>
    <visual>
      <origin xyz="0.0 0.0 0.0" rpy="0.0 0.0 0.0" />
      <geometry>
        <mesh filename="../meshes/torso_roll/component_22_22-133-296.STL" />
      </geometry>
      <material name="Polymethylmethacrylate_Clear">
        <color rgba="0.333 0.333 0.333 0.5" />
      </material>
    </visual>
    <collision>
      <origin xyz="0.186794 0.0 -0.0053567" rpy="-1.5708 0.0 0.0" />
      <geometry>
        <box size="0.42 0.3 0.284" />
      </geometry>
    </collision>
    <collision>
      <origin xyz="0.533639 0.0 0.0352469" rpy="0.0 0.0 0.0" />
      <geometry>
        <sphere radius="0.095" />
      </geometry>
    </collision>
  </link>
  <joint name="imu_torso" type="fixed">
    <origin xyz="0.29201 0.0 0.1147" rpy="3.14159 -1.5708 0.0" />
    <parent link="torso_roll" />
    <child link="imu_torso" />
  </joint>
  <link name="imu_torso">
    <inertial>
      <origin xyz="-0.00564954 -0.0076969 0.00128756" rpy="0.0 0.0 0.0" />
      <mass value="0.0102286" />
      <inertia ixx="9.63262e-07" ixy="-1.77855e-10" ixz="3.76127e-08" iyy="7.46825e-07" iyz="4.92881e-11" izz="1.45547e-06" />
    </inertial>
  </link>
  <joint name="left_arm_ee" type="fixed">
    <origin xyz="0.320542 -0.121136 0.0039" rpy="0.0 -1.5708 0.0" />
    <parent link="torso_roll" />
    <child link="left_arm_ee_link" />
  </joint>
  <link name="left_arm_ee_link" />
  <joint name="left_torso_motor_pitch" type="revolute">
    <origin xyz="0.029 -0.0375 0.0" rpy="-1.5708 0.0 0.0" />
    <parent link="torso_roll" />
    <child link="left_torso_motor_pitch_link" />
    <axis xyz="0.0 0.0 1.0" />
    <limit lower="-0.335" upper="0.761" effort="143.0" velocity="7.4" />
  </joint>
  <link name="left_torso_motor_pitch_link">
    <inertial>
      <origin xyz="0.0042399 0.03486 -0.0028492" rpy="0.0 0.0 0.0" />
      <mass value="0.19749" />
      <inertia ixx="0.00038814" ixy="-3.4222e-05" ixz="-2.6124e-06" iyy="0.00011093" iyz="-2.1479e-05" izz="0.0004666" />
    </inertial>
    <visual>
      <origin xyz="0.0 0.0 0.0" rpy="0.0 0.0 0.0" />
      <geometry>
        <mesh filename="../meshes/left_torso_motor_pitch_link/component_0_22-32-160.STL" />
      </geometry>
      <material name="Aluminum_Cast">
        <color rgba="0.555 0.555 0.555 1.0" />
      </material>
    </visual>
    <visual>
      <origin xyz="0.0 0.0 0.0" rpy="0.0 0.0 0.0" />
      <geometry>
        <mesh filename="../meshes/left_torso_motor_pitch_link/component_1_22-32-23-323.STL" />
      </geometry>
      <material name="Aluminum_Cast">
        <color rgba="0.555 0.555 0.555 1.0" />
      </material>
    </visual>
    <visual>
      <origin xyz="0.0 0.0 0.0" rpy="0.0 0.0 0.0" />
      <geometry>
        <mesh filename="../meshes/left_torso_motor_pitch_link/component_2_22-32-157.STL" />
      </geometry>
      <material name="Aluminum_Cast">
        <color rgba="0.555 0.555 0.555 1.0" />
      </material>
    </visual>
  </link>
  <joint name="upper_left_link_pitch" type="revolute">
    <origin xyz="0.0102625 0.0843782 0.001" rpy="3.14159 0.0 1.5708" />
    <parent link="left_torso_motor_pitch_link" />
    <child link="upper_left_link_pitch" />
    <axis xyz="0.0 0.0 -1.0" />
    <limit lower="-1.0" upper="1.0" effort="0.0" velocity="0.0" />
  </joint>
  <link name="upper_left_link_pitch">
    <inertial>
      <origin xyz="-2.63047e-08 3.26981e-08 3.72827e-13" rpy="0.0 0.0 0.0" />
      <mass value="0.0173132" />
      <inertia ixx="6.55433e-07" ixy="2.47822e-11" ixz="0.0" iyy="6.55422e-07" iyz="0.0" izz="8.9947e-07" />
    </inertial>
    <visual>
      <origin xyz="0.0 0.0 0.0" rpy="0.0 0.0 0.0" />
      <geometry>
        <mesh filename="../meshes/upper_left_link_pitch/component_0_22-32-135-23-22.STL" />
      </geometry>
      <material name="Aluminum_Cast">
        <color rgba="0.555 0.555 0.555 1.0" />
      </material>
    </visual>
  </link>
  <joint name="left_upper_link_roll" type="revolute">
    <origin xyz="0.0 0.0 0.0" rpy="-1.5708 0.0 1.5708" />
    <parent link="upper_left_link_pitch" />
    <child link="left_upper_link_roll" />
    <axis xyz="0.0 0.0 -1.0" />
    <limit lower="-0.6" upper="0.6" effort="0.0" velocity="0.0" />
  </joint>
  <link name="left_upper_link_roll">
    <inertial>
      <origin xyz="-0.0245646 -1.13711e-07 0.00388669" rpy="0.0 0.0 0.0" />
      <mass value="0.133017" />
      <inertia ixx="1.36976e-05" ixy="-2.64576e-07" ixz="1.24781e-05" iyy="0.000101179" iyz="-1.67536e-06" izz="9.05558e-05" />
    </inertial>
    <visual>
      <origin xyz="0.0 0.0 0.0" rpy="0.0 0.0 0.0" />
      <geometry>
        <mesh filename="../meshes/left_upper_link_roll/component_0_22-32-135-23-21.STL" />
      </geometry>
      <material name="Aluminum_Cast">
        <color rgba="0.555 0.555 0.555 1.0" />
      </material>
    </visual>
    <visual>
      <origin xyz="0.0 0.0 0.0" rpy="0.0 0.0 0.0" />
      <geometry>
        <mesh filename="../meshes/left_upper_link_roll/component_1_22-32-135-21.STL" />
      </geometry>
      <material name="Aluminum_Cast">
        <color rgba="0.555 0.555 0.555 1.0" />
      </material>
    </visual>
  </link>
  <joint name="left_low_link_roll" type="revolute">
    <origin xyz="-0.0592625 0.0 0.0093782" rpy="0.0 0.0 3.14159" />
    <parent link="left_upper_link_roll" />
    <child link="left_low_link_roll" />
    <axis xyz="0.0 0.0 -1.0" />
    <limit lower="-0.6" upper="0.6" effort="0.0" velocity="0.0" />
  </joint>
  <link name="left_low_link_roll">
    <inertial>
      <origin xyz="9.98998e-06 7.74708e-07 -2.56759e-06" rpy="0.0 0.0 0.0" />
      <mass value="0.0227526" />
      <inertia ixx="1.64452e-06" ixy="-3.36957e-08" ixz="-6.98846e-09" iyy="2.78761e-06" iyz="2.14131e-07" izz="1.68114e-06" />
    </inertial>
    <visual>
      <origin xyz="0.0 0.0 0.0" rpy="0.0 0.0 0.0" />
      <geometry>
        <mesh filename="../meshes/left_low_link_roll/component_0_22-32-135-27-21.STL" />
      </geometry>
      <material name="Aluminum_Cast">
        <color rgba="0.555 0.555 0.555 1.0" />
      </material>
    </visual>
  </link>
  <joint name="left_low_link_pitch" type="revolute">
    <origin xyz="0.0 0.0 0.0" rpy="-1.5708 0.0 0.0" />
    <parent link="left_low_link_roll" />
    <child link="left_low_link_pitch" />
    <axis xyz="0.0 0.0 1.0" />
    <limit lower="-1.0" upper="1.0" effort="0.0" velocity="0.0" />
  </joint>
  <link name="left_low_link_pitch">
    <inertial>
      <origin xyz="9.75123e-09 -4.08168e-08 0.0" rpy="0.0 0.0 0.0" />
      <mass value="0.0173132" />
      <inertia ixx="6.5545e-07" ixy="1.14678e-11" ixz="0.0" iyy="6.55404e-07" iyz="0.0" izz="8.9947e-07" />
    </inertial>
    <visual>
      <origin xyz="0.0 0.0 0.0" rpy="0.0 0.0 0.0" />
      <geometry>
        <mesh filename="../meshes/left_low_link_pitch/component_0_22-32-135-27-22.STL" />
      </geometry>
      <material name="Aluminum_Cast">
        <color rgba="0.555 0.555 0.555 1.0" />
      </material>
    </visual>
  </link>
  <joint name="right_arm_ee" type="fixed">
    <origin xyz="0.320542 0.121136 0.0039" rpy="0.0 -1.5708 0.0" />
    <parent link="torso_roll" />
    <child link="right_arm_ee_link" />
  </joint>
  <link name="right_arm_ee_link" />
  <joint name="right_torso_motor_pitch_link" type="revolute">
    <origin xyz="0.029 0.0375 0.0" rpy="1.5708 0.0 0.0" />
    <parent link="torso_roll" />
    <child link="right_torso_motor_pitch_link" />
    <axis xyz="0.0 0.0 1.0" />
    <limit lower="-0.761" upper="0.335" effort="143.0" velocity="7.4" />
  </joint>
  <link name="right_torso_motor_pitch_link">
    <inertial>
      <origin xyz="0.00423989 -0.0348602 -0.00280921" rpy="0.0 0.0 0.0" />
      <mass value="0.197487" />
      <inertia ixx="0.0003882" ixy="3.42217e-05" ixz="-2.65994e-06" iyy="0.000110994" iyz="2.18699e-05" izz="0.000466597" />
    </inertial>
    <visual>
      <origin xyz="0.0 0.0 0.0" rpy="0.0 0.0 0.0" />
      <geometry>
        <mesh filename="../meshes/right_torso_motor_pitch_link/component_0_22-32-27-323.STL" />
      </geometry>
      <material name="Aluminum_Cast">
        <color rgba="0.555 0.555 0.555 1.0" />
      </material>
    </visual>
    <visual>
      <origin xyz="0.0 0.0 0.0" rpy="0.0 0.0 0.0" />
      <geometry>
        <mesh filename="../meshes/right_torso_motor_pitch_link/component_1_22-32-147.STL" />
      </geometry>
      <material name="Aluminum_Cast">
        <color rgba="0.555 0.555 0.555 1.0" />
      </material>
    </visual>
    <visual>
      <origin xyz="0.0 0.0 0.0" rpy="0.0 0.0 0.0" />
      <geometry>
        <mesh filename="../meshes/right_torso_motor_pitch_link/component_2_22-32-146.STL" />
      </geometry>
      <material name="Aluminum_Cast">
        <color rgba="0.555 0.555 0.555 1.0" />
      </material>
    </visual>
  </link>
  <joint name="right_upper_link_pitch" type="revolute">
    <origin xyz="0.0102625 -0.0843782 0.001" rpy="0.0 0.0 -1.5708" />
    <parent link="right_torso_motor_pitch_link" />
    <child link="right_upper_link_pitch" />
    <axis xyz="0.0 0.0 1.0" />
    <limit lower="-1.0" upper="1.0" effort="0.0" velocity="0.0" />
  </joint>
  <link name="right_upper_link_pitch">
    <inertial>
      <origin xyz="-8.74203e-09 -4.10448e-08 0.0" rpy="0.0 0.0 0.0" />
      <mass value="0.0173132" />
      <inertia ixx="6.5545e-07" ixy="-1.03384e-11" ixz="0.0" iyy="6.55404e-07" iyz="0.0" izz="8.9947e-07" />
    </inertial>
    <visual>
      <origin xyz="0.0 0.0 0.0" rpy="0.0 0.0 0.0" />
      <geometry>
        <mesh filename="../meshes/right_upper_link_pitch/component_0_22-32-131-23-22.STL" />
      </geometry>
      <material name="Aluminum_Cast">
        <color rgba="0.555 0.555 0.555 1.0" />
      </material>
    </visual>
  </link>
  <joint name="right_upper_link_roll" type="revolute">
    <origin xyz="0.0 0.0 0.0" rpy="-1.5708 0.0 1.5708" />
    <parent link="right_upper_link_pitch" />
    <child link="right_upper_link_roll" />
    <axis xyz="0.0 0.0 1.0" />
    <limit lower="-0.6" upper="0.6" effort="0.0" velocity="0.0" />
  </joint>
  <link name="right_upper_link_roll">
    <inertial>
      <origin xyz="-0.0245641 6.49884e-09 0.00388577" rpy="0.0 0.0 0.0" />
      <mass value="0.133017" />
      <inertia ixx="1.36894e-05" ixy="6.31168e-09" ixz="1.24327e-05" iyy="0.000101503" iyz="4.00641e-08" izz="9.02475e-05" />
    </inertial>
    <visual>
      <origin xyz="0.0 0.0 0.0" rpy="0.0 0.0 0.0" />
      <geometry>
        <mesh filename="../meshes/right_upper_link_roll/component_0_22-32-131-23-21.STL" />
      </geometry>
      <material name="Aluminum_Cast">
        <color rgba="0.555 0.555 0.555 1.0" />
      </material>
    </visual>
    <visual>
      <origin xyz="0.0 0.0 0.0" rpy="0.0 0.0 0.0" />
      <geometry>
        <mesh filename="../meshes/right_upper_link_roll/component_1_22-32-131-21.STL" />
      </geometry>
      <material name="Aluminum_Cast">
        <color rgba="0.555 0.555 0.555 1.0" />
      </material>
    </visual>
  </link>
  <joint name="right_low_link_roll" type="revolute">
    <origin xyz="-0.0592625 0.0 0.0093782" rpy="0.0 0.0 3.14159" />
    <parent link="right_upper_link_roll" />
    <child link="right_low_link_roll" />
    <axis xyz="0.0 0.0 -1.0" />
    <limit lower="-0.6" upper="0.6" effort="0.0" velocity="0.0" />
  </joint>
  <link name="right_low_link_roll">
    <inertial>
      <origin xyz="8.69773e-06 1.84086e-08 5.59835e-06" rpy="0.0 0.0 0.0" />
      <mass value="0.0227526" />
      <inertia ixx="1.6429e-06" ixy="8.14768e-10" ixz="1.2443e-09" iyy="2.82858e-06" iyz="-5.12014e-09" izz="1.64179e-06" />
    </inertial>
    <visual>
      <origin xyz="0.0 0.0 0.0" rpy="0.0 0.0 0.0" />
      <geometry>
        <mesh filename="../meshes/right_low_link_roll/component_0_22-32-131-27-21.STL" />
      </geometry>
      <material name="Aluminum_Cast">
        <color rgba="0.555 0.555 0.555 1.0" />
      </material>
    </visual>
  </link>
  <joint name="right_low_link_pitch" type="revolute">
    <origin xyz="0.0 0.0 0.0" rpy="-1.5708 0.0 0.0" />
    <parent link="right_low_link_roll" />
    <child link="right_low_link_pitch" />
    <axis xyz="0.0 0.0 1.0" />
    <limit lower="-1.0" upper="1.0" effort="0.0" velocity="0.0" />
  </joint>
  <link name="right_low_link_pitch">
    <inertial>
      <origin xyz="3.66496e-08 2.04427e-08 0.0" rpy="0.0 0.0 0.0" />
      <mass value="0.0173132" />
      <inertia ixx="6.55414e-07" ixy="-2.15869e-11" ixz="0.0" iyy="6.5544e-07" iyz="0.0" izz="8.9947e-07" />
    </inertial>
    <visual>
      <origin xyz="0.0 0.0 0.0" rpy="0.0 0.0 0.0" />
      <geometry>
        <mesh filename="../meshes/right_low_link_pitch/component_0_22-32-131-27-22.STL" />
      </geometry>
      <material name="Aluminum_Cast">
        <color rgba="0.555 0.555 0.555 1.0" />
      </material>
    </visual>
  </link>
  <joint name="zed_lower_ee" type="fixed">
    <origin xyz="0.438759 -0.00025 0.0712677" rpy="0.0 -0.959931 -3.14159" />
    <parent link="torso_roll" />
    <child link="zed_lower_ee" />
  </joint>
  <link name="zed_lower_ee" />
  <joint name="zed_upper_ee" type="fixed">
    <origin xyz="0.561639 -0.00025 0.0915332" rpy="0.0 -1.5708 0.0" />
    <parent link="torso_roll" />
    <child link="zed_upper_ee" />
  </joint>
  <link name="zed_upper_ee" />
</robot>